Workbook
Name ДаНет: Тех.Лист!$A$1:$A$2

Sheet 01
E1: _____________________________ Согласовано
C2: 46082 | F2: Реестр разбит по Юр. лицам!!! КРУТИТЕ ВНИЗ
A4: ФАБРИКА ПРОЕКТОВ | E4: =SUM(E5:E6) -> 0
A5: Счет Альфа 1674
A6: счет СБЕР 6989
A8: № п/п | B8: Инициатор платежа | C8: Контрагент - Получатель | D8: Договор/Счет | E8: Сумма к оплате | F8: Назначение платежа | G8: Бюджет/Статья | H8: Наличие Договора | I8: Примечание | J8: Отметка об оплате | K8: Спец. Распоряжение / Приоритет
B9: Коммерческая деятельность (Закупка ТМЦ Снабжение / Логистика / Транзит)
A10: 1
A11: 2
A12: 3
A13: 4
A14: 5
A15: 6
A16: 7
A17: 8
A18: 9
A19: 10
A20: 11
A21: 12
... A59: 50
B60: АХР (Продажи / IT служба / Юр служба / ФЭО /Секретариат)
A61: 1
A62: 2
A63: 3
A64: 4
A65: 5
B66: Бухгалтерия (Налоги / ЗП / ЕСН / прочие платежи бух. службы)
A67: 1
A68: 2
A69: 3
A70: 4
A71: 5
A72: ИТОГО ФАБРИКА ПРОЕКТОВ РАСХОДЫ ПО РЕЕСТРУ | E72: =SUM(E9:E71) -> 0
A73: ДЕФИЦИТ / ПРОФИЦИТ с Остатка на начало дня | E73: =E4-E72 -> 0

Sheet 02
E1: _____________________________ Согласовано
C2: ='01'!C2+1 -> 46083 | F2: Реестр разбит по Юр. лицам!!! КРУТИТЕ ВНИЗ
A4: ФАБРИКА ПРОЕКТОВ | E4: =SUM(E5:E6) -> 87344.23 | F4: Реестр закрыт!!!
A5: Счет Альфа 1674 | E5: 85663.59
A6: счет СБЕР 6989 | E6: 1680.64
A8: № п/п | B8: Инициатор платежа | C8: Контрагент - Получатель | D8: Договор/Счет | E8: Сумма к оплате | F8: Назначение платежа | G8: Бюджет/Статья | H8: Наличие Договора | I8: Примечание | J8: Отметка об оплате | K8: Спец. Распоряжение / Приоритет
B9: Коммерческая деятельность (Закупка ТМЦ Снабжение / Логистика / Транзит)
A10: 1
A11: 2
A12: 3
A13: 4
A14: 5
A15: 6
A16: 7
A17: 8
A18: 9
A19: 10
A20: 11
A21: 12
... A59: 50
B60: АХР (Продажи / IT служба / Юр служба / ФЭО /Секретариат)
A61: 1
A62: 2
A63: 3
A64: 4
A65: 5
B66: Бухгалтерия (Налоги / ЗП / ЕСН / прочие платежи бух. службы)
A67: 1
A68: 2
A69: 3
A70: 4
A71: 5
A72: ИТОГО ФАБРИКА ПРОЕКТОВ РАСХОДЫ ПО РЕЕСТРУ | E72: =SUM(E9:E71) -> 0
A73: ДЕФИЦИТ / ПРОФИЦИТ с Остатка на начало дня | E73: =E4-E72 -> 87344.23

Sheet 03
E1: _____________________________ Согласовано
C2: ='02'!C2+1 -> 46084 | F2: Реестр разбит по Юр. лицам!!! КРУТИТЕ ВНИЗ
A4: ФАБРИКА ПРОЕКТОВ | E4: =SUM(E5:E6) -> 87344.23 | F4: Реестр закрыт!!!
A5: Счет Альфа 1674 | E5: 85663.59 | F5: 135 400 с РИК
A6: счет СБЕР 6989 | E6: 1680.64 | F6: 20 000 с УК
A8: № п/п | B8: Инициатор платежа | C8: Контрагент - Получатель | D8: Договор/Счет | E8: Сумма к оплате | F8: Назначение платежа | G8: Бюджет/Статья | H8: Наличие Договора | I8: Примечание | J8: Отметка об оплате | K8: Спец. Распоряжение / Приоритет
B9: Коммерческая деятельность (Закупка ТМЦ Снабжение / Логистика / Транзит)
A10: 1 | B10: Лещенко В.А. | C10: ООО ГЕРМЕС | D10: Счет № 493 от 24.10.2025 | E10: .218750 | F10: Закупка бетона | G10: Бюджет | H10: Да | I10: ГП 294 Забор. ИП Малый. Договор №ФП31072025 от 31.07.2025 Приложение №2
A11: =A10+1 -> 2 | B11: Лещенко В.А. | C11: ООО "Айрон" | D11: Счет №АИПП-2504 от 21.03.2025 | E11: .=16534 | F11: Закупка металла. | G11: Бюджет | H11: Да | I11: (Щепкино. СПА.стены)ИП Малый Договор подряда №ФП-03022025 от 03.02.2025 Пр. №2 от 03.02.2025 ИП Малый
A12: =A11+1 -> 3 | B12: Лещенко В.А. | C12: ООО "Айрон" | D12: Счет № АИПП-3664 от 25.04.2025 | E12: .126845 | F12: Закупка металла на объект | G12: Бюджет | H12: Да | I12: ГП 204 (Навес) Договор подряда №ФП-27032025 от 27.03.2025 Приложение № 2 от 27.03.2025
A13: =A12+1 -> 4 | B13: Лещенко В.А. | C13: ООО "Айрон" | D13: Счет № АИПП-3754 от 29.04.2025 | E13: .27325 | F13: Закупка металла. | G13: Бюджет | H13: Да | I13: ГП 204(навес) Договор подряда №ФП-27032025 от 27.03.2025 Приложение №2 от 27.03.2025
A14: =A13+1 -> 5 | B14: Лещенко В.А. | C14: ООО "Айрон" | D14: Счет № АИПП-5404 от 30.06.2025 | E14: .150100 | F14: Закупка металла на объект | G14: Бюджет | H14: Да | I14: ГП 294. ХБП ИП Малый Договор подряда №ФП-19062025 от 19.06.2025 Приложение №2 от 19.06.2025
A15: =A14+1 -> 6 | B15: Лещенко В.А. | C15: ООО "Айрон" | D15: Счет № АИПП-5407 от 30.06.2025 | E15: .17300 | F15: Закупка металла на объект | G15: Бюджет | H15: Да | I15: ГП 204. ИП Малый. Договор подряда №ФП-27032025 от 27.03.2025 Приложение №2 от 27.03.2025
A16: =A15+1 -> 7 | B16: Лещенко В.А. | C16: ООО "Айрон" | D16: Счет № АИПП-5408 от 30.06.2025 | E16: .35505 | F16: Закупка металла на объект | G16: Бюджет | H16: Да | I16: ГП 13. (ХБП) ИП Малый. Договор подряда №ФП-10660-72/01 от 12.02.2024 г. Приложение №1/8 от 14.03.2025
A17: =A16+1 -> 8 | B17: Лещенко В.А. | C17: ООО "Айрон" | D17: Счет № АИПП-6301 от 04.08.2025 | E17: .163370 | F17: Закупка металла на объект | G17: Бюджет | H17: Да | I17: ГП 326. Забор ИП Малый
A18: =A17+1 -> 9 | B18: Лещенко В.А. | C18: ООО "Айрон" | D18: Счет № АИПП-6303 от 04.08.2025 | E18: .115500 | F18: Закупка металла на объект | G18: Бюджет | H18: Да | I18: ГП 294. Бассеин ИП Малый
A19: =A18+1 -> 10 | B19: Лещенко В.А. | C19: ООО "Айрон" | D19: Счет № АИПП-6304 от 04.08.2025 | E19: .51000 | F19: Закупка металла на объект | G19: Бюджет | H19: Да | I19: ГП 294. Забор ИП Малый
A20: =A19+1 -> 11 | B20: Лещенко В.А. | C20: ИП Полежаев А.А. | D20: Счет № 42 от 26.09.2025 | E20: .363298 | F20: Устройство фасада с молдингами на ХБП по дог.№ФП-10660-29 от 16.09.2022, пр.№ 1/19 | G20: Бюджет | H20: Да | I20: Окончательный ГП 326
A21: =A20+1 -> 12 | B21: Лещенко В.А. | C21: ИП Полежаев А.А. | D21: Счет № 44 от 30.09.2025 | E21: .313500 | F21: Устройство фасада с молдингами на ХБП. Договор подряда №ФП-10660-29 от 16.09.2022 Приложение № 1/25 | G21: Бюджет | H21: Да | I21: Аванс ГП 294,295
A22: =A21+1 -> 13 | B22: Малый П.А. | C22: ИП Полежаев А.А. | D22: Счёт №50 от 26.11.2025 | E22: .538264 | F22: Устройство фасада с молдингами | G22: Бюджет | H22: Да | I22: Окончательный ГП-243
A23: =A22+1 -> 14 | B23: Малый П.А. | C23: ИП Полежаев А.А. | D23: Счёт№51 от 02.12.2025 | E23: .54956 | F23: Устройство калон террасы | G23: Бюджет | I23: Окончательный. ГП-294.295 Договор подряда№ФП-10660-29 ОТ 16.09.2022
A24: =A23+1 -> 15 | B24: Малый П.А. | C24: ИП Полежаев А.А. | D24: Счёт№53 от 20.01.2025 | E24: .842553 | F24: Фасад | I24: ГП-148 Дог№-ФП-25112024-01от 25.11.2024 ПР№2 от 25.11.2024
A25: =A24+1 -> 16 | B25: Малый П.А. | C25: ИП Чередниченко | D25: Счёт № 17 от 05.12.2025. | E25: .112952 | F25: Монтаж натяжных потолков | G25: Бюджет | H25: да | I25: ГП-138 Дог-10660-84/01от01.10.2024
A26: =A25+1 -> 17 | B26: Лещенко В.А. | C26: ИП Любомирский В.Г. | D26: Счет № 20 от 28.07.2025 | E26: .558077 | F26: Электромонтажные работы | G26: Бюджет | H26: Да | I26: Вн. рынок. Щепкин СПА
A27: =A26+1 -> 18 | B27: Салпагаров Р.А. | C27: ИП Любомирский В.Г. | D27: Счет № 25 от 23.09.2025 | E27: .210906 | F27: Оплата работ по пр.1/12 от 22.09.25 к дог.№ФП-10660-10/01 от 19.03.2024г | G27: Бюджет | H27: Да | I27: ГП 13. Электрика. 4й этап
A28: =A27+1 -> 19 | B28: Малый П.А. | C28: ИП Кравченко К.Н. | D28: Счёт№542 от 24.10.2025 | E28: .32621,5 | F28: Пиломатериалы | G28: Бюджет | H28: Да | I28: Вн.Рынок. Щепкино, кровля
A29: =A28+1 -> 20 | B29: Малый П.А. | C29: ИП Кравченко К.Н. | D29: Счёт №548 от 28.10.2025 | E29: .38400 | F29: Пиломатериалы | G29: Бюджет | H29: Да | I29: Вн.Рынок. Щепкино,кровля
A30: =A29+1 -> 21 | B30: Малый П.А. | C30: ИП Кравченко К.Н. | D30: Счёт №566 от 19.11.2025 | E30: .38400 | F30: Пиломатериалы | G30: Бюджет | H30: Да | I30: Навес ГП 262
A31: =A30+1 -> 22 | B31: Малый П.А. | C31: ИП Кравченко К.Н. | D31: Счёт № 609 от 22.12.2025 | E31: .128725,35 | F31: Пиломатериалы | G31: Бюджет | I31: Навес ГП 262
A32: =A31+1 -> 23 | B32: Синицына В.В. | C32: ИП Храмова Э.Э. | D32: Счет №2042 от 17.11.2025 | E32: .42000 | F32: Услуги по благоустройству территории с 10.11.2025 по 13.11.2025 | G32: Бюджет | H32: Да
A33: =A32+1 -> 24 | B33: Малый П.А. | C33: ИП Храмова Э.Э | D33: Счёт№2177от 08.12.2025 | E33: .16800 | F33: Благоустройство территории | G33: Бюджет | I33: ГП-103 Дог№ФП-10660-36 Планирование грунта
A34: =A33+1 -> 25 | B34: Малый П.А. | C34: ИП Храмова Э.Э. | D34: Счёт№2233 от 15.12.2025 | E34: .8400 | F34: Благоустройство территории | G34: Бюджет | I34: ГП-218,231,213,214,216,221,188 Дог№10660-36 от 15.032023 чистка преддомовых территорий
A35: =A34+1 -> 26 | B35: Синицына В.В. | C35: ИП Храмова Э.Э. | D35: Счет №2252 от 22.12.2025 | E35: .42000 | F35: Услуги по благоустройству территории | G35: Бюджет
A36: =A35+1 -> 27 | B36: Синицына В.В. | C36: ИП Храмова Э.Э. | D36: Счет №2301 от 25.12.2025г. | E36: .25200 | F36: Услуги по благоустройству территории | G36: Бюджет
A37: =A36+1 -> 28 | B37: Салпагаров Р.А. | C37: ИП Сердечная О.Ю. | D37: Счет № 291 от 17.09.2025 | E37: .59500 | F37: Договор №3 от 30.03.2022 г. Транспортные услуги по перевозке опалубки, 05.09.2025 г.,16.09.2025 г. | G37: Бюджет | H37: Да | I37: ГП 294. Бассейн.ИП Малый
A38: =A37+1 -> 29 | B38: Салпагаров Р.А. | C38: ИП Козлова Н.В. | D38: Счет № 27 от 19.11.2024 | E38: .=30500 | F38: Ус-во фасада по дог.№ФП-10660-93 от 01.10.2024 от 19.11.2024 | G38: Бюджет | H38: Да | I38: Окончательный.ГП-211
A39: =A38+1 -> 30 | B39: Салпагаров Р.А. | C39: ООО "АЛЮМИНИУМ" | D39: Счет № 385 от 03.09.2025 | E39: .386200 | F39: Оплата за алюмииевые конструкции по дог.№ФП-28052024 от 28.05.2025 | G39: Бюджет | H39: Да | I39: ГП 291. Витражи.
A40: =A39+1 -> 31 | B40: Синицына В.В. | C40: ИП Никулов А.В. | D40: Счет №113 от 21.11.2025 | E40: .=146016/2 | F40: Аванс по Приложению 1/14 к Договору №ФП-10660-98 от 04.04.2025 | G40: Бюджет | I40: Монтаж системы полива на придомовой ГП 273, 280
A41: =A40+1 -> 32 | B41: Лещенко В.А. | C41: ИП Стрельцов В.А. | D41: Счет № 23 от 07.11.2025 | E41: .600050 | F41: Устройство приточно-вытяжной вентиляции согласно Приложения №1/13 от 11.06.2025г. к Договору подряда №ФП-10660-53/01 от 08.10.2024 г. | G41: Бюджет | H41: Да | I41: ГП 291. Вентиляция
A42: =A41+1 -> 33 | B42: Малый П.А. | C42: ИП Алты-Садых С.Ю | D42: Счёт№18/2 от 15.12.2025 | E42: .109250 | F42: Окончательный платеж за работы, изготовление,монтаж,шлифовку пропитку и окраску деревянных элементов террасы | G42: Бюджет | H42: да | I42: ГП-148 Дог№-ФП-10660-31 ОТ 14.11.2022
...

Sheet 04
E1: _____________________________ Согласовано
C2: ='03'!C2+1 -> 46085 | F2: Реестр разбит по Юр. лицам!!! КРУТИТЕ ВНИЗ
A4: ФАБРИКА ПРОЕКТОВ | E4: =SUM(E5:E6) -> 4253.41 | F4: Реестр закрыт!!!
A5: Счет Альфа 1674 | E5: 2572.77
A6: счет СБЕР 6989 | E6: 1680.64
A8: № п/п | B8: Инициатор платежа | C8: Контрагент - Получатель | D8: Договор/Счет | E8: Сумма к оплате | F8: Назначение платежа | G8: Бюджет/Статья | H8: Наличие Договора | I8: Примечание | J8: Отметка об оплате | K8: Спец. Распоряжение / Приоритет
B9: Коммерческая деятельность (Закупка ТМЦ Снабжение / Логистика / Транзит)
A10: 1
A11: 2
A12: 3
A13: 4
A14: 5
A15: 6
A16: 7
A17: 8
A18: 9
A19: 10
A20: 11
A21: 12
... A59: 50
B60: АХР (Продажи / IT служба / Юр служба / ФЭО /Секретариат)
A61: 1
A62: 2
A63: 3
A64: 4
A65: 5
B66: Бухгалтерия (Налоги / ЗП / ЕСН / прочие платежи бух. службы)
A67: 1
A68: 2
A69: 3
A70: 4
A71: 5
A72: ИТОГО ФАБРИКА ПРОЕКТОВ РАСХОДЫ ПО РЕЕСТРУ | E72: =SUM(E9:E71) -> 0
A73: ДЕФИЦИТ / ПРОФИЦИТ с Остатка на начало дня | E73: =E4-E72 -> 4253.41

Sheet 05
E1: _____________________________ Согласовано
C2: ='04'!C2+1 -> 46086 | F2: Реестр разбит по Юр. лицам!!! КРУТИТЕ ВНИЗ
A4: ФАБРИКА ПРОЕКТОВ | E4: =SUM(E5:E6) -> 166889.41 | F4: Реестр закрыт!!!
A5: Счет Альфа 1674 | E5: 165208.77
A6: счет СБЕР 6989 | E6: 1680.64
A8: № п/п | B8: Инициатор платежа | C8: Контрагент - Получатель | D8: Договор/Счет | E8: Сумма к оплате | F8: Назначение платежа | G8: Бюджет/Статья | H8: Наличие Договора | I8: Примечание | J8: Отметка об оплате | K8: Спец. Распоряжение / Приоритет
B9: Коммерческая деятельность (Закупка ТМЦ Снабжение / Логистика / Транзит)
A10: 1 | B10: Лещенко В.А. | C10: ООО ГЕРМЕС | D10: Счет № 493 от 24.10.2025 | E10: .218750 | F10: Закупка бетона | G10: Бюджет | H10: Да | I10: ГП 294 Забор. ИП Малый. Договор №ФП31072025 от 31.07.2025 Приложение №2
A11: =A10+1 -> 2 | B11: Лещенко В.А. | C11: ООО "Айрон" | D11: Счет №АИПП-2504 от 21.03.2025 | E11: .=16534 | F11: Закупка металла. | G11: Бюджет | H11: Да | I11: (Щепкино. СПА.стены)ИП Малый Договор подряда №ФП-03022025 от 03.02.2025 Пр. №2 от 03.02.2025 ИП Малый
A12: =A11+1 -> 3 | B12: Лещенко В.А. | C12: ООО "Айрон" | D12: Счет № АИПП-3664 от 25.04.2025 | E12: .126845 | F12: Закупка металла на объект | G12: Бюджет | H12: Да | I12: ГП 204 (Навес) Договор подряда №ФП-27032025 от 27.03.2025 Приложение № 2 от 27.03.2025
A13: =A12+1 -> 4 | B13: Лещенко В.А. | C13: ООО "Айрон" | D13: Счет № АИПП-3754 от 29.04.2025 | E13: .27325 | F13: Закупка металла. | G13: Бюджет | H13: Да | I13: ГП 204(навес) Договор подряда №ФП-27032025 от 27.03.2025 Приложение №2 от 27.03.2025
A14: =A13+1 -> 5 | B14: Лещенко В.А. | C14: ООО "Айрон" | D14: Счет № АИПП-5404 от 30.06.2025 | E14: .150100 | F14: Закупка металла на объект | G14: Бюджет | H14: Да | I14: ГП 294. ХБП ИП Малый Договор подряда №ФП-19062025 от 19.06.2025 Приложение №2 от 19.06.2025
A15: =A14+1 -> 6 | B15: Лещенко В.А. | C15: ООО "Айрон" | D15: Счет № АИПП-5407 от 30.06.2025 | E15: .17300 | F15: Закупка металла на объект | G15: Бюджет | H15: Да | I15: ГП 204. ИП Малый. Договор подряда №ФП-27032025 от 27.03.2025 Приложение №2 от 27.03.2025
A16: =A15+1 -> 7 | B16: Лещенко В.А. | C16: ООО "Айрон" | D16: Счет № АИПП-5408 от 30.06.2025 | E16: .35505 | F16: Закупка металла на объект | G16: Бюджет | H16: Да | I16: ГП 13. (ХБП) ИП Малый. Договор подряда №ФП-10660-72/01 от 12.02.2024 г. Приложение №1/8 от 14.03.2025
A17: =A16+1 -> 8 | B17: Лещенко В.А. | C17: ООО "Айрон" | D17: Счет № АИПП-6301 от 04.08.2025 | E17: .163370 | F17: Закупка металла на объект | G17: Бюджет | H17: Да | I17: ГП 326. Забор ИП Малый
A18: =A17+1 -> 9 | B18: Лещенко В.А. | C18: ООО "Айрон" | D18: Счет № АИПП-6303 от 04.08.2025 | E18: .115500 | F18: Закупка металла на объект | G18: Бюджет | H18: Да | I18: ГП 294. Бассеин ИП Малый
A19: =A18+1 -> 10 | B19: Лещенко В.А. | C19: ООО "Айрон" | D19: Счет № АИПП-6304 от 04.08.2025 | E19: .51000 | F19: Закупка металла на объект | G19: Бюджет | H19: Да | I19: ГП 294. Забор ИП Малый
A20: =A19+1 -> 11 | B20: Лещенко В.А. | C20: ИП Полежаев А.А. | D20: Счет № 42 от 26.09.2025 | E20: .363298 | F20: Устройство фасада с молдингами на ХБП по дог.№ФП-10660-29 от 16.09.2022, пр.№ 1/19 | G20: Бюджет | H20: Да | I20: Окончательный ГП 326
A21: =A20+1 -> 12 | B21: Лещенко В.А. | C21: ИП Полежаев А.А. | D21: Счет № 44 от 30.09.2025 | E21: .313500 | F21: Устройство фасада с молдингами на ХБП. Договор подряда №ФП-10660-29 от 16.09.2022 Приложение № 1/25 | G21: Бюджет | H21: Да | I21: Аванс ГП 294,295
A22: =A21+1 -> 13 | B22: Малый П.А. | C22: ИП Полежаев А.А. | D22: Счёт №50 от 26.11.2025 | E22: .538264 | F22: Устройство фасада с молдингами | G22: Бюджет | H22: Да | I22: Окончательный ГП-243
A23: =A22+1 -> 14 | B23: Малый П.А. | C23: ИП Полежаев А.А. | D23: Счёт№51 от 02.12.2025 | E23: .54956 | F23: Устройство калон террасы | G23: Бюджет | I23: Окончательный. ГП-294.295 Договор подряда№ФП-10660-29 ОТ 16.09.2022
A24: =A23+1 -> 15 | B24: Малый П.А. | C24: ИП Полежаев А.А. | D24: Счёт№53 от 20.01.2025 | E24: .842553 | F24: Фасад | I24: ГП-148 Дог№-ФП-25112024-01от 25.11.2024 ПР№2 от 25.11.2024
A25: =A24+1 -> 16 | B25: Малый П.А. | C25: ИП Чередниченко | D25: Счёт № 17 от 05.12.2025. | E25: .112952 | F25: Монтаж натяжных потолков | G25: Бюджет | H25: да | I25: ГП-138 Дог-10660-84/01от01.10.2024
A26: =A25+1 -> 17 | B26: Лещенко В.А. | C26: ИП Любомирский В.Г. | D26: Счет № 20 от 28.07.2025 | E26: .558077 | F26: Электромонтажные работы | G26: Бюджет | H26: Да | I26: Вн. рынок. Щепкин СПА
A27: =A26+1 -> 18 | B27: Салпагаров Р.А. | C27: ИП Любомирский В.Г. | D27: Счет № 25 от 23.09.2025 | E27: .210906 | F27: Оплата работ по пр.1/12 от 22.09.25 к дог.№ФП-10660-10/01 от 19.03.2024г | G27: Бюджет | H27: Да | I27: ГП 13. Электрика. 4й этап
A28: =A27+1 -> 19 | B28: Малый П.А. | C28: ИП Кравченко К.Н. | D28: Счёт№542 от 24.10.2025 | E28: .32621,5 | F28: Пиломатериалы | G28: Бюджет | H28: Да | I28: Вн.Рынок. Щепкино, кровля
A29: =A28+1 -> 20 | B29: Малый П.А. | C29: ИП Кравченко К.Н. | D29: Счёт №548 от 28.10.2025 | E29: .38400 | F29: Пиломатериалы | G29: Бюджет | H29: Да | I29: Вн.Рынок. Щепкино,кровля
A30: =A29+1 -> 21 | B30: Малый П.А. | C30: ИП Кравченко К.Н. | D30: Счёт №566 от 19.11.2025 | E30: .38400 | F30: Пиломатериалы | G30: Бюджет | H30: Да | I30: Навес ГП 262
A31: =A30+1 -> 22 | B31: Малый П.А. | C31: ИП Кравченко К.Н. | D31: Счёт № 609 от 22.12.2025 | E31: .128725,35 | F31: Пиломатериалы | G31: Бюджет | I31: Навес ГП 262
A32: =A31+1 -> 23 | B32: Синицына В.В. | C32: ИП Храмова Э.Э. | D32: Счет №2042 от 17.11.2025 | E32: .42000 | F32: Услуги по благоустройству территории с 10.11.2025 по 13.11.2025 | G32: Бюджет | H32: Да
A33: =A32+1 -> 24 | B33: Малый П.А. | C33: ИП Храмова Э.Э | D33: Счёт№2177от 08.12.2025 | E33: .16800 | F33: Благоустройство территории | G33: Бюджет | I33: ГП-103 Дог№ФП-10660-36 Планирование грунта
A34: =A33+1 -> 25 | B34: Малый П.А. | C34: ИП Храмова Э.Э. | D34: Счёт№2233 от 15.12.2025 | E34: .8400 | F34: Благоустройство территории | G34: Бюджет | I34: ГП-218,231,213,214,216,221,188 Дог№10660-36 от 15.032023 чистка преддомовых территорий
A35: =A34+1 -> 26 | B35: Синицына В.В. | C35: ИП Храмова Э.Э. | D35: Счет №2252 от 22.12.2025 | E35: .42000 | F35: Услуги по благоустройству территории | G35: Бюджет
A36: =A35+1 -> 27 | B36: Синицына В.В. | C36: ИП Храмова Э.Э. | D36: Счет №2301 от 25.12.2025г. | E36: .25200 | F36: Услуги по благоустройству территории | G36: Бюджет
A37: =A36+1 -> 28 | B37: Салпагаров Р.А. | C37: ИП Сердечная О.Ю. | D37: Счет № 291 от 17.09.2025 | E37: .59500 | F37: Договор №3 от 30.03.2022 г. Транспортные услуги по перевозке опалубки, 05.09.2025 г.,16.09.2025 г. | G37: Бюджет | H37: Да | I37: ГП 294. Бассейн.ИП Малый
A38: =A37+1 -> 29 | B38: Салпагаров Р.А. | C38: ИП Козлова Н.В. | D38: Счет № 27 от 19.11.2024 | E38: .=30500 | F38: Ус-во фасада по дог.№ФП-10660-93 от 01.10.2024 от 19.11.2024 | G38: Бюджет | H38: Да | I38: Окончательный.ГП-211
A39: =A38+1 -> 30 | B39: Салпагаров Р.А. | C39: ООО "АЛЮМИНИУМ" | D39: Счет № 385 от 03.09.2025 | E39: .386200 | F39: Оплата за алюмииевые конструкции по дог.№ФП-28052024 от 28.05.2025 | G39: Бюджет | H39: Да | I39: ГП 291. Витражи.
A40: =A39+1 -> 31 | B40: Синицына В.В. | C40: ИП Никулов А.В. | D40: Счет №113 от 21.11.2025 | E40: .=146016/2 | F40: Аванс по Приложению 1/14 к Договору №ФП-10660-98 от 04.04.2025 | G40: Бюджет | I40: Монтаж системы полива на придомовой ГП 273, 280
A41: =A40+1 -> 32 | B41: Лещенко В.А. | C41: ИП Стрельцов В.А. | D41: Счет № 23 от 07.11.2025 | E41: .600050 | F41: Устройство приточно-вытяжной вентиляции согласно Приложения №1/13 от 11.06.2025г. к Договору подряда №ФП-10660-53/01 от 08.10.2024 г. | G41: Бюджет | H41: Да | I41: ГП 291. Вентиляция
A42: =A41+1 -> 33 | B42: Малый П.А. | C42: ИП Алты-Садых С.Ю | D42: Счёт№18/2 от 15.12.2025 | E42: .109250 | F42: Окончательный платеж за работы, изготовление,монтаж,шлифовку пропитку и окраску деревянных элементов террасы | G42: Бюджет | H42: да | I42: ГП-148 Дог№-ФП-10660-31 ОТ 14.11.2022
...

Sheet 06
E1: _____________________________ Согласовано
C2: ='05'!C2+1 -> 46087 | F2: Реестр разбит по Юр. лицам!!! КРУТИТЕ ВНИЗ
A4: ФАБРИКА ПРОЕКТОВ | E4: =SUM(E5:E6) -> 351809.41 | F4: Реестр закрыт!!!
A5: Счет Альфа 1674 | E5: 350128.77
A6: счет СБЕР 6989 | E6: 1680.64
A8: № п/п | B8: Инициатор платежа | C8: Контрагент - Получатель | D8: Договор/Счет | E8: Сумма к оплате | F8: Назначение платежа | G8: Бюджет/Статья | H8: Наличие Договора | I8: Примечание | J8: Отметка об оплате | K8: Спец. Распоряжение / Приоритет
B9: Коммерческая деятельность (Закупка ТМЦ Снабжение / Логистика / Транзит)
A10: 1
A11: 2
A12: 3
A13: 4
A14: 5
A15: 6
A16: 7
A17: 8
A18: 9
A19: 10
A20: 11
A21: 12
... A59: 50
B60: АХР (Продажи / IT служба / Юр служба / ФЭО /Секретариат)
A61: 1
A62: 2
A63: 3
A64: 4
A65: 5
B66: Бухгалтерия (Налоги / ЗП / ЕСН / прочие платежи бух. службы)
A67: 1
A68: 2
A69: 3
A70: 4
A71: 5
A72: ИТОГО ФАБРИКА ПРОЕКТОВ РАСХОДЫ ПО РЕЕСТРУ | E72: =SUM(E9:E71) -> 0
A73: ДЕФИЦИТ / ПРОФИЦИТ с Остатка на начало дня | E73: =E4-E72 -> 351809.41

Sheet 07
E1: _____________________________ Согласовано
C2: ='06'!C2+1 -> 46088 | F2: Реестр разбит по Юр. лицам!!! КРУТИТЕ ВНИЗ
A4: ФАБРИКА ПРОЕКТОВ | E4: =SUM(E5:E6) -> 0
A5: Счет Альфа 1674
A6: счет СБЕР 6989
A8: № п/п | B8: Инициатор платежа | C8: Контрагент - Получатель | D8: Договор/Счет | E8: Сумма к оплате | F8: Назначение платежа | G8: Бюджет/Статья | H8: Наличие Договора | I8: Примечание | J8: Отметка об оплате | K8: Спец. Распоряжение / Приоритет
B9: Коммерческая деятельность (Закупка ТМЦ Снабжение / Логистика / Транзит)
A10: 1
A11: 2
A12: 3
A13: 4
A14: 5
A15: 6
A16: 7
A17: 8
A18: 9
A19: 10
A20: 11
A21: 12
... A59: 50
B60: АХР (Продажи / IT служба / Юр служба / ФЭО /Секретариат)
A61: 1
A62: 2
A63: 3
A64: 4
A65: 5
B66: Бухгалтерия (Налоги / ЗП / ЕСН / прочие платежи бух. службы)
A67: 1
A68: 2
A69: 3
A70: 4
A71: 5
A72: ИТОГО ФАБРИКА ПРОЕКТОВ РАСХОДЫ ПО РЕЕСТРУ | E72: =SUM(E9:E71) -> 0
A73: ДЕФИЦИТ / ПРОФИЦИТ с Остатка на начало дня | E73: =E4-E72 -> 0

Sheet 08
E1: _____________________________ Согласовано
C2: ='07'!C2+1 -> 46089 | F2: Реестр разбит по Юр. лицам!!! КРУТИТЕ ВНИЗ
A4: ФАБРИКА ПРОЕКТОВ | E4: =SUM(E5:E6) -> 0
A5: Счет Альфа 1674
A6: счет СБЕР 6989
A8: № п/п | B8: Инициатор платежа | C8: Контрагент - Получатель | D8: Договор/Счет | E8: Сумма к оплате | F8: Назначение платежа | G8: Бюджет/Статья | H8: Наличие Договора | I8: Примечание | J8: Отметка об оплате | K8: Спец. Распоряжение / Приоритет
B9: Коммерческая деятельность (Закупка ТМЦ Снабжение / Логистика / Транзит)
A10: 1
A11: 2
A12: 3
A13: 4
A14: 5
A15: 6
A16: 7
A17: 8
A18: 9
A19: 10
A20: 11
A21: 12
... A59: 50
B60: АХР (Продажи / IT служба / Юр служба / ФЭО /Секретариат)
A61: 1
A62: 2
A63: 3
A64: 4
A65: 5
B66: Бухгалтерия (Налоги / ЗП / ЕСН / прочие платежи бух. службы)
A67: 1
A68: 2
A69: 3
A70: 4
A71: 5
A72: ИТОГО ФАБРИКА ПРОЕКТОВ РАСХОДЫ ПО РЕЕСТРУ | E72: =SUM(E9:E71) -> 0
A73: ДЕФИЦИТ / ПРОФИЦИТ с Остатка на начало дня | E73: =E4-E72 -> 0

Sheet 09
E1: _____________________________ Согласовано
C2: ='08'!C2+1 -> 46090 | F2: Реестр разбит по Юр. лицам!!! КРУТИТЕ ВНИЗ
A4: ФАБРИКА ПРОЕКТОВ | E4: =SUM(E5:E6) -> 0
A5: Счет Альфа 1674
A6: счет СБЕР 6989
A8: № п/п | B8: Инициатор платежа | C8: Контрагент - Получатель | D8: Договор/Счет | E8: Сумма к оплате | F8: Назначение платежа | G8: Бюджет/Статья | H8: Наличие Договора | I8: Примечание | J8: Отметка об оплате | K8: Спец. Распоряжение / Приоритет
B9: Коммерческая деятельность (Закупка ТМЦ Снабжение / Логистика / Транзит)
A10: 1
A11: 2
A12: 3
A13: 4
A14: 5
A15: 6
A16: 7
A17: 8
A18: 9
A19: 10
A20: 11
A21: 12
... A59: 50
B60: АХР (Продажи / IT служба / Юр служба / ФЭО /Секретариат)
A61: 1
A62: 2
A63: 3
A64: 4
A65: 5
B66: Бухгалтерия (Налоги / ЗП / ЕСН / прочие платежи бух. службы)
A67: 1
A68: 2
A69: 3
A70: 4
A71: 5
A72: ИТОГО ФАБРИКА ПРОЕКТОВ РАСХОДЫ ПО РЕЕСТРУ | E72: =SUM(E9:E71) -> 0
A73: ДЕФИЦИТ / ПРОФИЦИТ с Остатка на начало дня | E73: =E4-E72 -> 0

Sheet 10
E1: _____________________________ Согласовано
C2: ='09'!C2+1 -> 46091 | F2: Реестр разбит по Юр. лицам!!! КРУТИТЕ ВНИЗ
A4: ФАБРИКА ПРОЕКТОВ | E4: =SUM(E5:E6) -> 350128.77 | F4: Реестр закрыт!!!
A5: Счет Альфа 1674 | E5: 350128.77 | F5: 7 000 с ЯП
A6: счет СБЕР 6989 | E6: .1680,64
A8: № п/п | B8: Инициатор платежа | C8: Контрагент - Получатель | D8: Договор/Счет | E8: Сумма к оплате | F8: Назначение платежа | G8: Бюджет/Статья | H8: Наличие Договора | I8: Примечание | J8: Отметка об оплате | K8: Спец. Распоряжение / Приоритет
B9: Коммерческая деятельность (Закупка ТМЦ Снабжение / Логистика / Транзит)
A10: 1
A11: 2
A12: 3
A13: 4
A14: 5
A15: 6
A16: 7
A17: 8
A18: 9
A19: 10
A20: 11
A21: 12
... A59: 50
B60: АХР (Продажи / IT служба / Юр служба / ФЭО /Секретариат)
A61: 1 | B61: Амитон Д.Д. | C61: ПАО Вымпелком | D61: счёт 101189501178 от 28.02.26 | E61: .6019,15 | F61: оплата услуг связи
A62: 2
A63: 3
A64: 4
A65: 5
B66: Бухгалтерия (Налоги / ЗП / ЕСН / прочие платежи бух. службы)
A67: 1 | B67: Дмитриева О. В. | C67: Альфа-Банк | D67: реестр | E67: 354888.1 | F67: зарплата за февраль 2026 г. | J67: на обработке
A68: 2 | B68: Дмитриева О. В. | C68: ИФНС по ЕНП | D68: КБК 18201061201010000510 | E68: .225000 | F68: Страховые взносы за февраль 2026 г (налоги с фот)
A69: 3 | B69: Дмитриева О. В. | C69: ИФНС по ЕНП | D69: КБК 182 01 06 12 01 01 0000 510 | E69: .42000 | F69: НДФЛ (период с 23.02-28.02.2026) | I69: срок оплаты до 05.03.26
A70: 4 | B70: Дмитриева О. В. | C70: ИФНС по ЕНП | D70: КБК 182 01 06 12 01 01 0000 510 | E70: .73000 | F70: НДФЛ (период с 01.02-22.02.2026) | I70: срок оплаты до 02.03.26
A71: ИТОГО ФАБРИКА ПРОЕКТОВ РАСХОДЫ ПО РЕЕСТРУ | E71: =SUM(E9:E70) -> 354888.1
A72: ДЕФИЦИТ / ПРОФИЦИТ с Остатка на начало дня | E72: =E4-E71 -> -4759.33

Sheet 11
E1: _____________________________ Согласовано
C2: ='10'!C2+1 -> 46092 | F2: Реестр разбит по Юр. лицам!!! КРУТИТЕ ВНИЗ
A4: ФАБРИКА ПРОЕКТОВ | E4: =SUM(E5:E6) -> 3921.31 | F4: Реестр закрыт!!!
A5: Счет Альфа 1674 | E5: 2240.67
A6: счет СБЕР 6989 | E6: 1680.64
A8: № п/п | B8: Инициатор платежа | C8: Контрагент - Получатель | D8: Договор/Счет | E8: Сумма к оплате | F8: Назначение платежа | G8: Бюджет/Статья | H8: Наличие Договора | I8: Примечание | J8: Отметка об оплате | K8: Спец. Распоряжение / Приоритет
B9: Коммерческая деятельность (Закупка ТМЦ Снабжение / Логистика / Транзит)
A10: 1
A11: 2
A12: 3
A13: 4
A14: 5
A15: 6
A16: 7
A17: 8
A18: 9
A19: 10
A20: 11
A21: 12
... A59: 50
B60: АХР (Продажи / IT служба / Юр служба / ФЭО /Секретариат)
A61: 1
A62: 2
A63: 3
A64: 4
A65: 5
B66: Бухгалтерия (Налоги / ЗП / ЕСН / прочие платежи бух. службы)
A67: 1
A68: 2
A69: 3
A70: 4
A71: 5
A72: ИТОГО ФАБРИКА ПРОЕКТОВ РАСХОДЫ ПО РЕЕСТРУ | E72: =SUM(E9:E71) -> 0
A73: ДЕФИЦИТ / ПРОФИЦИТ с Остатка на начало дня | E73: =E4-E72 -> 3921.31

Sheet 12
E1: _____________________________ Согласовано
C2: ='11'!C2+1 -> 46093 | F2: Реестр разбит по Юр. лицам!!! КРУТИТЕ ВНИЗ
A4: ФАБРИКА ПРОЕКТОВ | E4: =SUM(E5:E6) -> 3921.31 | F4: Реестр закрыт!!!
A5: Счет Альфа 1674 | E5: 2240.67
A6: счет СБЕР 6989 | E6: 1680.64
A8: № п/п | B8: Инициатор платежа | C8: Контрагент - Получатель | D8: Договор/Счет | E8: Сумма к оплате | F8: Назначение платежа | G8: Бюджет/Статья | H8: Наличие Договора | I8: Примечание | J8: Отметка об оплате | K8: Спец. Распоряжение / Приоритет
B9: Коммерческая деятельность (Закупка ТМЦ Снабжение / Логистика / Транзит)
A10: 1 | B10: Малый П.А. | C10: ИП Храмова Э.Э. | D10: Счёт№389 от 10.03.2026 | E10: .12600 | F10: Услуги по благоустройству територии | H10: Да | I10: Дог №ФП-10660 от 15.03.2023
A11: 2 | B11: Малый П.А. | C11: ИП Кривошлыкова | D11: Счёт№42 от 11.03.2026 | E11: .27200 | F11: Транспортные услуги | H11: Да | I11: ГП 385 Фундамент
A12: 3
A13: 4
A14: 5
A15: 6
A16: 7
A17: 8
A18: 9
A19: 10
A20: 11
A21: 12
A22: 13
A23: 14
... A59: 50
B60: АХР (Продажи / IT служба / Юр служба / ФЭО /Секретариат)
A61: 1 | B61: Амитон Д.Д. | C61: ООО Яндекс 360 для бизнеса | D61: счёт ЛС-5001476685-1 от 11 марта 2026 г. | E61: .3326 | F61: оплата доступа к сервису электронной почты | H61: Да
A62: 2
A63: 3
A64: 4
A65: 5
B66: Бухгалтерия (Налоги / ЗП / ЕСН / прочие платежи бух. службы)
A67: 1
A68: 2
A69: 3
A70: 4
A71: 5
A72: ИТОГО ФАБРИКА ПРОЕКТОВ РАСХОДЫ ПО РЕЕСТРУ | E72: =SUM(E9:E71) -> 0
A73: ДЕФИЦИТ / ПРОФИЦИТ с Остатка на начало дня | E73: =E4-E72 -> 3921.31

Sheet 13
E1: _____________________________ Согласовано
C2: ='12'!C2+1 -> 46094 | F2: Реестр разбит по Юр. лицам!!! КРУТИТЕ ВНИЗ
A4: ФАБРИКА ПРОЕКТОВ | E4: =SUM(E5:E6) -> 3921.31 | F4: Реестр закрыт!!!
A5: Счет Альфа 1674 | E5: 2240.67
A6: счет СБЕР 6989 | E6: 1680.64
A8: № п/п | B8: Инициатор платежа | C8: Контрагент - Получатель | D8: Договор/Счет | E8: Сумма к оплате | F8: Назначение платежа | G8: Бюджет/Статья | H8: Наличие Договора | I8: Примечание | J8: Отметка об оплате | K8: Спец. Распоряжение / Приоритет
B9: Коммерческая деятельность (Закупка ТМЦ Снабжение / Логистика / Транзит)
A10: 1
A11: 2
A12: 3
A13: 4
A14: 5
A15: 6
A16: 7
A17: 8
A18: 9
A19: 10
A20: 11
A21: 12
... A59: 50
B60: АХР (Продажи / IT служба / Юр служба / ФЭО /Секретариат)
A61: 1
A62: 2
A63: 3
A64: 4
A65: 5
B66: Бухгалтерия (Налоги / ЗП / ЕСН / прочие платежи бух. службы)
A67: 1
A68: 2
A69: 3
A70: 4
A71: 5
A72: ИТОГО ФАБРИКА ПРОЕКТОВ РАСХОДЫ ПО РЕЕСТРУ | E72: =SUM(E9:E71) -> 0
A73: ДЕФИЦИТ / ПРОФИЦИТ с Остатка на начало дня | E73: =E4-E72 -> 3921.31

Sheet 14
E1: _____________________________ Согласовано
C2: ='13'!C2+1 -> 46095 | F2: Реестр разбит по Юр. лицам!!! КРУТИТЕ ВНИЗ
A4: ФАБРИКА ПРОЕКТОВ | E4: =SUM(E5:E6) -> 0
A5: Счет Альфа 1674
A6: счет СБЕР 6989
A8: № п/п | B8: Инициатор платежа | C8: Контрагент - Получатель | D8: Договор/Счет | E8: Сумма к оплате | F8: Назначение платежа | G8: Бюджет/Статья | H8: Наличие Договора | I8: Примечание | J8: Отметка об оплате | K8: Спец. Распоряжение / Приоритет
B9: Коммерческая деятельность (Закупка ТМЦ Снабжение / Логистика / Транзит)
A10: 1
A11: 2
A12: 3
A13: 4
A14: 5
A15: 6
A16: 7
A17: 8
A18: 9
A19: 10
A20: 11
A21: 12
... A59: 50
B60: АХР (Продажи / IT служба / Юр служба / ФЭО /Секретариат)
A61: 1
A62: 2
A63: 3
A64: 4
A65: 5
B66: Бухгалтерия (Налоги / ЗП / ЕСН / прочие платежи бух. службы)
A67: 1
A68: 2
A69: 3
A70: 4
A71: 5
A72: ИТОГО ФАБРИКА ПРОЕКТОВ РАСХОДЫ ПО РЕЕСТРУ | E72: =SUM(E9:E71) -> 0
A73: ДЕФИЦИТ / ПРОФИЦИТ с Остатка на начало дня | E73: =E4-E72 -> 0

Sheet 15
E1: _____________________________ Согласовано
C2: ='14'!C2+1 -> 46096 | F2: Реестр разбит по Юр. лицам!!! КРУТИТЕ ВНИЗ
A4: ФАБРИКА ПРОЕКТОВ | E4: =SUM(E5:E6) -> 0
A5: Счет Альфа 1674
A6: счет СБЕР 6989
A8: № п/п | B8: Инициатор платежа | C8: Контрагент - Получатель | D8: Договор/Счет | E8: Сумма к оплате | F8: Назначение платежа | G8: Бюджет/Статья | H8: Наличие Договора | I8: Примечание | J8: Отметка об оплате | K8: Спец. Распоряжение / Приоритет
B9: Коммерческая деятельность (Закупка ТМЦ Снабжение / Логистика / Транзит)
A10: 1
A11: 2
A12: 3
A13: 4
A14: 5
A15: 6
A16: 7
A17: 8
A18: 9
A19: 10
A20: 11
A21: 12
... A59: 50
B60: АХР (Продажи / IT служба / Юр служба / ФЭО /Секретариат)
A61: 1
A62: 2
A63: 3
A64: 4
A65: 5
B66: Бухгалтерия (Налоги / ЗП / ЕСН / прочие платежи бух. службы)
A67: 1
A68: 2
A69: 3
A70: 4
A71: 5
A72: ИТОГО ФАБРИКА ПРОЕКТОВ РАСХОДЫ ПО РЕЕСТРУ | E72: =SUM(E9:E71) -> 0
A73: ДЕФИЦИТ / ПРОФИЦИТ с Остатка на начало дня | E73: =E4-E72 -> 0

Sheet 16
E1: _____________________________ Согласовано
C2: ='15'!C2+1 -> 46097 | F2: Реестр разбит по Юр. лицам!!! КРУТИТЕ ВНИЗ
A4: ФАБРИКА ПРОЕКТОВ | E4: =SUM(E5:E6) -> 161921.31 | F4: Реестр закрыт!!!
A5: Счет Альфа 1674 | E5: 160240.67
A6: счет СБЕР 6989 | E6: 1680.64
A8: № п/п | B8: Инициатор платежа | C8: Контрагент - Получатель | D8: Договор/Счет | E8: Сумма к оплате | F8: Назначение платежа | G8: Бюджет/Статья | H8: Наличие Договора | I8: Примечание | J8: Отметка об оплате | K8: Спец. Распоряжение / Приоритет
B9: Коммерческая деятельность (Закупка ТМЦ Снабжение / Логистика / Транзит)
A10: 1
A11: 2
A12: 3
A13: 4
A14: 5
A15: 6
A16: 7
A17: 8
A18: 9
A19: 10
A20: 11
A21: 12
... A59: 50
B60: АХР (Продажи / IT служба / Юр служба / ФЭО /Секретариат)
A61: 1
A62: 2
A63: 3
A64: 4
A65: 5
B66: Бухгалтерия (Налоги / ЗП / ЕСН / прочие платежи бух. службы)
A67: 1
A68: 2
A69: 3
A70: 4
A71: 5
A72: ИТОГО ФАБРИКА ПРОЕКТОВ РАСХОДЫ ПО РЕЕСТРУ | E72: =SUM(E9:E71) -> 0
A73: ДЕФИЦИТ / ПРОФИЦИТ с Остатка на начало дня | E73: =E4-E72 -> 161921.31

Sheet 17
E1: _____________________________ Согласовано
C2: ='16'!C2+1 -> 46098 | F2: Реестр разбит по Юр. лицам!!! КРУТИТЕ ВНИЗ
A4: ФАБРИКА ПРОЕКТОВ | E4: =SUM(E5:E6) -> 161921.31 | F4: Реестр закрыт!!!
A5: Счет Альфа 1674 | E5: 160240.67
A6: счет СБЕР 6989 | E6: 1680.64
A8: № п/п | B8: Инициатор платежа | C8: Контрагент - Получатель | D8: Договор/Счет | E8: Сумма к оплате | F8: Назначение платежа | G8: Бюджет/Статья | H8: Наличие Договора | I8: Примечание | J8: Отметка об оплате | K8: Спец. Распоряжение / Приоритет
B9: Коммерческая деятельность (Закупка ТМЦ Снабжение / Логистика / Транзит)
A10: 1 | B10: Лещенко В.А. | C10: ООО ГЕРМЕС | D10: Счет № 493 от 24.10.2025 | E10: .218750 | F10: Закупка бетона | G10: Бюджет | H10: Да | I10: ГП 294 Забор. ИП Малый. Договор №ФП31072025 от 31.07.2025 Приложение №2
A11: =A10+1 -> 2 | B11: Лещенко В.А. | C11: ООО "Айрон" | D11: Счет №АИПП-2504 от 21.03.2025 | E11: .=16534 | F11: Закупка металла. | G11: Бюджет | H11: Да | I11: (Щепкино. СПА.стены)ИП Малый Договор подряда №ФП-03022025 от 03.02.2025 Пр. №2 от 03.02.2025 ИП Малый
A12: =A11+1 -> 3 | B12: Лещенко В.А. | C12: ООО "Айрон" | D12: Счет № АИПП-3664 от 25.04.2025 | E12: .126845 | F12: Закупка металла на объект | G12: Бюджет | H12: Да | I12: ГП 204 (Навес) Договор подряда №ФП-27032025 от 27.03.2025 Приложение № 2 от 27.03.2025
A13: =A12+1 -> 4 | B13: Лещенко В.А. | C13: ООО "Айрон" | D13: Счет № АИПП-3754 от 29.04.2025 | E13: .27325 | F13: Закупка металла. | G13: Бюджет | H13: Да | I13: ГП 204(навес) Договор подряда №ФП-27032025 от 27.03.2025 Приложение №2 от 27.03.2025
A14: =A13+1 -> 5 | B14: Лещенко В.А. | C14: ООО "Айрон" | D14: Счет № АИПП-5404 от 30.06.2025 | E14: .150100 | F14: Закупка металла на объект | G14: Бюджет | H14: Да | I14: ГП 294. ХБП ИП Малый Договор подряда №ФП-19062025 от 19.06.2025 Приложение №2 от 19.06.2025
A15: =A14+1 -> 6 | B15: Лещенко В.А. | C15: ООО "Айрон" | D15: Счет № АИПП-5407 от 30.06.2025 | E15: .17300 | F15: Закупка металла на объект | G15: Бюджет | H15: Да | I15: ГП 204. ИП Малый. Договор подряда №ФП-27032025 от 27.03.2025 Приложение №2 от 27.03.2025
A16: =A15+1 -> 7 | B16: Лещенко В.А. | C16: ООО "Айрон" | D16: Счет № АИПП-5408 от 30.06.2025 | E16: .35505 | F16: Закупка металла на объект | G16: Бюджет | H16: Да | I16: ГП 13. (ХБП) ИП Малый. Договор подряда №ФП-10660-72/01 от 12.02.2024 г. Приложение №1/8 от 14.03.2025
A17: =A16+1 -> 8 | B17: Лещенко В.А. | C17: ООО "Айрон" | D17: Счет № АИПП-6301 от 04.08.2025 | E17: .163370 | F17: Закупка металла на объект | G17: Бюджет | H17: Да | I17: ГП 326. Забор ИП Малый
A18: =A17+1 -> 9 | B18: Лещенко В.А. | C18: ООО "Айрон" | D18: Счет № АИПП-6303 от 04.08.2025 | E18: .115500 | F18: Закупка металла на объект | G18: Бюджет | H18: Да | I18: ГП 294. Бассеин ИП Малый
A19: =A18+1 -> 10 | B19: Лещенко В.А. | C19: ООО "Айрон" | D19: Счет № АИПП-6304 от 04.08.2025 | E19: .51000 | F19: Закупка металла на объект | G19: Бюджет | H19: Да | I19: ГП 294. Забор ИП Малый
A20: =A19+1 -> 11 | B20: Лещенко В.А. | C20: ИП Полежаев А.А. | D20: Счет № 42 от 26.09.2025 | E20: .363298 | F20: Устройство фасада с молдингами на ХБП по дог.№ФП-10660-29 от 16.09.2022, пр.№ 1/19 | G20: Бюджет | H20: Да | I20: Окончательный ГП 326
A21: =A20+1 -> 12 | B21: Лещенко В.А. | C21: ИП Полежаев А.А. | D21: Счет № 44 от 30.09.2025 | E21: .313500 | F21: Устройство фасада с молдингами на ХБП. Договор подряда №ФП-10660-29 от 16.09.2022 Приложение № 1/25 | G21: Бюджет | H21: Да | I21: Аванс ГП 294,295
A22: =A21+1 -> 13 | B22: Малый П.А. | C22: ИП Полежаев А.А. | D22: Счёт №50 от 26.11.2025 | E22: .538264 | F22: Устройство фасада с молдингами | G22: Бюджет | H22: Да | I22: Окончательный ГП-243
A23: =A22+1 -> 14 | B23: Малый П.А. | C23: ИП Полежаев А.А. | D23: Счёт№51 от 02.12.2025 | E23: .54956 | F23: Устройство калон террасы | G23: Бюджет | I23: Окончательный. ГП-294.295 Договор подряда№ФП-10660-29 ОТ 16.09.2022
A24: =A23+1 -> 15 | B24: Малый П.А. | C24: ИП Полежаев А.А. | D24: Счёт№53 от 20.01.2025 | E24: .842553 | F24: Фасад | I24: ГП-148 Дог№-ФП-25112024-01от 25.11.2024 ПР№2 от 25.11.2024
A25: =A24+1 -> 16 | B25: Лещенко В.А. | C25: ИП Любомирский В.Г. | D25: Счет № 20 от 28.07.2025 | E25: .558077 | F25: Электромонтажные работы | G25: Бюджет | H25: Да | I25: Вн. рынок. Щепкин СПА
A26: =A25+1 -> 17 | B26: Лещенко В.А. | C26: ИП Любомирский В.Г. | D26: Счет № 25 от 23.09.2025 | E26: .210906 | F26: Оплата работ по пр.1/12 от 22.09.25 к дог.№ФП-10660-10/01 от 19.03.2024г | G26: Бюджет | H26: Да | I26: ГП 13. Электрика. 4й этап
A27: =A26+1 -> 18 | B27: Малый П.А. | C27: ИП Кравченко К.Н. | D27: Счёт№542 от 24.10.2025 | E27: .32621,5 | F27: Пиломатериалы | G27: Бюджет | H27: Да | I27: Вн.Рынок. Щепкино, кровля
A28: =A27+1 -> 19 | B28: Малый П.А. | C28: ИП Кравченко К.Н. | D28: Счёт №548 от 28.10.2025 | E28: .38400 | F28: Пиломатериалы | G28: Бюджет | H28: Да | I28: Вн.Рынок. Щепкино,кровля
A29: =A28+1 -> 20 | B29: Малый П.А. | C29: ИП Кравченко К.Н. | D29: Счёт №566 от 19.11.2025 | E29: .38400 | F29: Пиломатериалы | G29: Бюджет | H29: Да | I29: Навес ГП 262
A30: =A29+1 -> 21 | B30: Малый П.А. | C30: ИП Кравченко К.Н. | D30: Счёт № 609 от 22.12.2025 | E30: .128725,35 | F30: Пиломатериалы | G30: Бюджет | I30: Навес ГП 262
A31: =A30+1 -> 22 | B31: Синицына В.В. | C31: ИП Храмова Э.Э. | D31: Счет №2042 от 17.11.2025 | E31: .42000 | F31: Услуги по благоустройству территории с 10.11.2025 по 13.11.2025 | G31: Бюджет | H31: Да
A32: =A31+1 -> 23 | B32: Малый П.А. | C32: ИП Храмова Э.Э | D32: Счёт№2177от 08.12.2025 | E32: .16800 | F32: Благоустройство территории | G32: Бюджет | I32: ГП-103 Дог№ФП-10660-36 Планирование грунта
A33: =A32+1 -> 24 | B33: Малый П.А. | C33: ИП Храмова Э.Э. | D33: Счёт№2233 от 15.12.2025 | E33: .8400 | F33: Благоустройство территории | G33: Бюджет | I33: ГП-218,231,213,214,216,221,188 Дог№10660-36 от 15.032023 чистка преддомовых территорий
A34: =A33+1 -> 25 | B34: Синицына В.В. | C34: ИП Храмова Э.Э. | D34: Счет №2252 от 22.12.2025 | E34: .42000 | F34: Услуги по благоустройству территории | G34: Бюджет
A35: =A34+1 -> 26 | B35: Синицына В.В. | C35: ИП Храмова Э.Э. | D35: Счет №2301 от 25.12.2025г. | E35: .25200 | F35: Услуги по благоустройству территории | G35: Бюджет
A36: =A35+1 -> 27 | B36: Лещенко В.А. | C36: ИП Сердечная О.Ю. | D36: Счет № 291 от 17.09.2025 | E36: .59500 | F36: Договор №3 от 30.03.2022 г. Транспортные услуги по перевозке опалубки, 05.09.2025 г.,16.09.2025 г. | G36: Бюджет | H36: Да | I36: ГП 294. Бассейн.ИП Малый
A37: =A36+1 -> 28 | B37: Лещенко В.А. | C37: ИП Козлова Н.В. | D37: Счет № 27 от 19.11.2024 | E37: .=30500 | F37: Ус-во фасада по дог.№ФП-10660-93 от 01.10.2024 от 19.11.2024 | G37: Бюджет | H37: Да | I37: Окончательный.ГП-211
A38: =A37+1 -> 29 | B38: Лещенко В.А. | C38: ООО "АЛЮМИНИУМ" | D38: Счет № 385 от 03.09.2025 | E38: .386200 | F38: Оплата за алюмииевые конструкции по дог.№ФП-28052024 от 28.05.2025 | G38: Бюджет | H38: Да | I38: ГП 291. Витражи.
A39: =A38+1 -> 30 | B39: Синицына В.В. | C39: ИП Никулов А.В. | D39: Счет №113 от 21.11.2025 | E39: .=146016/2 | F39: Аванс по Приложению 1/14 к Договору №ФП-10660-98 от 04.04.2025 | G39: Бюджет | I39: Монтаж системы полива на придомовой ГП 273, 280
A40: =A39+1 -> 31 | B40: Лещенко В.А. | C40: ИП Стрельцов В.А. | D40: Счет № 23 от 07.11.2025 | E40: .600050 | F40: Устройство приточно-вытяжной вентиляции согласно Приложения №1/13 от 11.06.2025г. к Договору подряда №ФП-10660-53/01 от 08.10.2024 г. | G40: Бюджет | H40: Да | I40: ГП 291. Вентиляция
A41: =A40+1 -> 32 | B41: Малый П.А. | C41: ИП Алты-Садых С.Ю | D41: Счёт№18/2 от 15.12.2025 | E41: .109250 | F41: Окончательный платеж за работы, изготовление,монтаж,шлифовку пропитку и окраску деревянных элементов террасы | G41: Бюджет | H41: да | I41: ГП-148 Дог№-ФП-10660-31 ОТ 14.11.2022
A42: =A41+1 -> 33 | B42: Малый П.А. | C42: ИП Чеботарев А.В. | D42: Счет № 1369 от 11.09.2025 | E42: .107000 | F42: Разработка дизайн проекта. Пр.№ 1/2 к дог.№ФП-10660-101 от 21.08.2025 | G42: Бюджет | H42: Да | I42: ГП 146
...

Sheet 18
E1: _____________________________ Согласовано
C2: ='17'!C2+1 -> 46099 | F2: Реестр разбит по Юр. лицам!!! КРУТИТЕ ВНИЗ
A4: ФАБРИКА ПРОЕКТОВ | E4: =SUM(E5:E6) -> 43534.66 | F4: Реестр закрыт!!!
A5: Счет Альфа 1674 | E5: 41854.02
A6: счет СБЕР 6989 | E6: 1680.64
A8: № п/п | B8: Инициатор платежа | C8: Контрагент - Получатель | D8: Договор/Счет | E8: Сумма к оплате | F8: Назначение платежа | G8: Бюджет/Статья | H8: Наличие Договора | I8: Примечание | J8: Отметка об оплате | K8: Спец. Распоряжение / Приоритет
B9: Коммерческая деятельность (Закупка ТМЦ Снабжение / Логистика / Транзит)
A10: 1
A11: 2
A12: 3
A13: 4
A14: 5
A15: 6
A16: 7
A17: 8
A18: 9
A19: 10
A20: 11
A21: 12
... A59: 50
B60: АХР (Продажи / IT служба / Юр служба / ФЭО /Секретариат)
A61: 1
A62: 2
A63: 3
A64: 4
A65: 5
B66: Бухгалтерия (Налоги / ЗП / ЕСН / прочие платежи бух. службы)
A67: 1
A68: 2
A69: 3
A70: 4
A71: 5
A72: ИТОГО ФАБРИКА ПРОЕКТОВ РАСХОДЫ ПО РЕЕСТРУ | E72: =SUM(E9:E71) -> 0
A73: ДЕФИЦИТ / ПРОФИЦИТ с Остатка на начало дня | E73: =E4-E72 -> 43534.66

Sheet 19
E1: _____________________________ Согласовано
C2: ='18'!C2+1 -> 46100 | F2: Реестр разбит по Юр. лицам!!! КРУТИТЕ ВНИЗ
A4: ФАБРИКА ПРОЕКТОВ | E4: =SUM(E5:E6) -> 43534.66 | F4: Реестр закрыт!!!
A5: Счет Альфа 1674 | E5: 41854.02
A6: счет СБЕР 6989 | E6: 1680.64
A8: № п/п | B8: Инициатор платежа | C8: Контрагент - Получатель | D8: Договор/Счет | E8: Сумма к оплате | F8: Назначение платежа | G8: Бюджет/Статья | H8: Наличие Договора | I8: Примечание | J8: Отметка об оплате | K8: Спец. Распоряжение / Приоритет
B9: Коммерческая деятельность (Закупка ТМЦ Снабжение / Логистика / Транзит)
A10: 1 | B10: Лещенко В.А. | C10: ООО ГЕРМЕС | D10: Счет № 493 от 24.10.2025 | E10: .218750 | F10: Закупка бетона | G10: Бюджет | H10: Да | I10: ГП 294 Забор. ИП Малый. Договор №ФП31072025 от 31.07.2025 Приложение №2
A11: =A10+1 -> 2 | B11: Лещенко В.А. | C11: ООО "Айрон" | D11: Счет №АИПП-2504 от 21.03.2025 | E11: .=16534 | F11: Закупка металла. | G11: Бюджет | H11: Да | I11: (Щепкино. СПА.стены)ИП Малый Договор подряда №ФП-03022025 от 03.02.2025 Пр. №2 от 03.02.2025 ИП Малый
A12: =A11+1 -> 3 | B12: Лещенко В.А. | C12: ООО "Айрон" | D12: Счет № АИПП-3664 от 25.04.2025 | E12: .126845 | F12: Закупка металла на объект | G12: Бюджет | H12: Да | I12: ГП 204 (Навес) Договор подряда №ФП-27032025 от 27.03.2025 Приложение № 2 от 27.03.2025
A13: =A12+1 -> 4 | B13: Лещенко В.А. | C13: ООО "Айрон" | D13: Счет № АИПП-3754 от 29.04.2025 | E13: .27325 | F13: Закупка металла. | G13: Бюджет | H13: Да | I13: ГП 204(навес) Договор подряда №ФП-27032025 от 27.03.2025 Приложение №2 от 27.03.2025
A14: =A13+1 -> 5 | B14: Лещенко В.А. | C14: ООО "Айрон" | D14: Счет № АИПП-5404 от 30.06.2025 | E14: .150100 | F14: Закупка металла на объект | G14: Бюджет | H14: Да | I14: ГП 294. ХБП ИП Малый Договор подряда №ФП-19062025 от 19.06.2025 Приложение №2 от 19.06.2025
A15: =A14+1 -> 6 | B15: Лещенко В.А. | C15: ООО "Айрон" | D15: Счет № АИПП-5407 от 30.06.2025 | E15: .17300 | F15: Закупка металла на объект | G15: Бюджет | H15: Да | I15: ГП 204. ИП Малый. Договор подряда №ФП-27032025 от 27.03.2025 Приложение №2 от 27.03.2025
A16: =A15+1 -> 7 | B16: Лещенко В.А. | C16: ООО "Айрон" | D16: Счет № АИПП-5408 от 30.06.2025 | E16: .35505 | F16: Закупка металла на объект | G16: Бюджет | H16: Да | I16: ГП 13. (ХБП) ИП Малый. Договор подряда №ФП-10660-72/01 от 12.02.2024 г. Приложение №1/8 от 14.03.2025
A17: =A16+1 -> 8 | B17: Лещенко В.А. | C17: ООО "Айрон" | D17: Счет № АИПП-6301 от 04.08.2025 | E17: .163370 | F17: Закупка металла на объект | G17: Бюджет | H17: Да | I17: ГП 326. Забор ИП Малый
A18: =A17+1 -> 9 | B18: Лещенко В.А. | C18: ООО "Айрон" | D18: Счет № АИПП-6303 от 04.08.2025 | E18: .115500 | F18: Закупка металла на объект | G18: Бюджет | H18: Да | I18: ГП 294. Бассеин ИП Малый
A19: =A18+1 -> 10 | B19: Лещенко В.А. | C19: ООО "Айрон" | D19: Счет № АИПП-6304 от 04.08.2025 | E19: .51000 | F19: Закупка металла на объект | G19: Бюджет | H19: Да | I19: ГП 294. Забор ИП Малый
A20: =A19+1 -> 11 | B20: Лещенко В.А. | C20: ИП Полежаев А.А. | D20: Счет № 42 от 26.09.2025 | E20: .363298 | F20: Устройство фасада с молдингами на ХБП по дог.№ФП-10660-29 от 16.09.2022, пр.№ 1/19 | G20: Бюджет | H20: Да | I20: Окончательный ГП 326
A21: =A20+1 -> 12 | B21: Лещенко В.А. | C21: ИП Полежаев А.А. | D21: Счет № 44 от 30.09.2025 | E21: .313500 | F21: Устройство фасада с молдингами на ХБП. Договор подряда №ФП-10660-29 от 16.09.2022 Приложение № 1/25 | G21: Бюджет | H21: Да | I21: Аванс ГП 294,295
A22: =A21+1 -> 13 | B22: Малый П.А. | C22: ИП Полежаев А.А. | D22: Счёт №50 от 26.11.2025 | E22: .538264 | F22: Устройство фасада с молдингами | G22: Бюджет | H22: Да | I22: Окончательный ГП-243
A23: =A22+1 -> 14 | B23: Малый П.А. | C23: ИП Полежаев А.А. | D23: Счёт№51 от 02.12.2025 | E23: .54956 | F23: Устройство калон террасы | G23: Бюджет | I23: Окончательный. ГП-294.295 Договор подряда№ФП-10660-29 ОТ 16.09.2022
A24: =A23+1 -> 15 | B24: Малый П.А. | C24: ИП Полежаев А.А. | D24: Счёт№53 от 20.01.2025 | E24: .842553 | F24: Фасад | I24: ГП-148 Дог№-ФП-25112024-01от 25.11.2024 ПР№2 от 25.11.2024
A25: =A24+1 -> 16 | B25: Лещенко В.А. | C25: ИП Любомирский В.Г. | D25: Счет № 20 от 28.07.2025 | E25: .558077 | F25: Электромонтажные работы | G25: Бюджет | H25: Да | I25: Вн. рынок. Щепкин СПА
A26: =A25+1 -> 17 | B26: Лещенко В.А. | C26: ИП Любомирский В.Г. | D26: Счет № 25 от 23.09.2025 | E26: .210906 | F26: Оплата работ по пр.1/12 от 22.09.25 к дог.№ФП-10660-10/01 от 19.03.2024г | G26: Бюджет | H26: Да | I26: ГП 13. Электрика. 4й этап
A27: =A26+1 -> 18 | B27: Малый П.А. | C27: ИП Кравченко К.Н. | D27: Счёт№542 от 24.10.2025 | E27: .32621,5 | F27: Пиломатериалы | G27: Бюджет | H27: Да | I27: Вн.Рынок. Щепкино, кровля
A28: =A27+1 -> 19 | B28: Малый П.А. | C28: ИП Кравченко К.Н. | D28: Счёт №548 от 28.10.2025 | E28: .38400 | F28: Пиломатериалы | G28: Бюджет | H28: Да | I28: Вн.Рынок. Щепкино,кровля
A29: =A28+1 -> 20 | B29: Малый П.А. | C29: ИП Кравченко К.Н. | D29: Счёт №566 от 19.11.2025 | E29: .38400 | F29: Пиломатериалы | G29: Бюджет | H29: Да | I29: Навес ГП 262
A30: =A29+1 -> 21 | B30: Малый П.А. | C30: ИП Кравченко К.Н. | D30: Счёт № 609 от 22.12.2025 | E30: .128725,35 | F30: Пиломатериалы | G30: Бюджет | I30: Навес ГП 262
A31: =A30+1 -> 22 | B31: Синицына В.В. | C31: ИП Храмова Э.Э. | D31: Счет №2042 от 17.11.2025 | E31: .42000 | F31: Услуги по благоустройству территории с 10.11.2025 по 13.11.2025 | G31: Бюджет | H31: Да
A32: =A31+1 -> 23 | B32: Малый П.А. | C32: ИП Храмова Э.Э | D32: Счёт№2177от 08.12.2025 | E32: .16800 | F32: Благоустройство территории | G32: Бюджет | I32: ГП-103 Дог№ФП-10660-36 Планирование грунта
A33: =A32+1 -> 24 | B33: Малый П.А. | C33: ИП Храмова Э.Э. | D33: Счёт№2233 от 15.12.2025 | E33: .8400 | F33: Благоустройство территории | G33: Бюджет | I33: ГП-218,231,213,214,216,221,188 Дог№10660-36 от 15.032023 чистка преддомовых территорий
A34: =A33+1 -> 25 | B34: Синицына В.В. | C34: ИП Храмова Э.Э. | D34: Счет №2252 от 22.12.2025 | E34: .42000 | F34: Услуги по благоустройству территории | G34: Бюджет
A35: =A34+1 -> 26 | B35: Синицына В.В. | C35: ИП Храмова Э.Э. | D35: Счет №2301 от 25.12.2025г. | E35: .25200 | F35: Услуги по благоустройству территории | G35: Бюджет
A36: =A35+1 -> 27 | B36: Лещенко В.А. | C36: ИП Сердечная О.Ю. | D36: Счет № 291 от 17.09.2025 | E36: .59500 | F36: Договор №3 от 30.03.2022 г. Транспортные услуги по перевозке опалубки, 05.09.2025 г.,16.09.2025 г. | G36: Бюджет | H36: Да | I36: ГП 294. Бассейн.ИП Малый
A37: =A36+1 -> 28 | B37: Лещенко В.А. | C37: ИП Козлова Н.В. | D37: Счет № 27 от 19.11.2024 | E37: .=30500 | F37: Ус-во фасада по дог.№ФП-10660-93 от 01.10.2024 от 19.11.2024 | G37: Бюджет | H37: Да | I37: Окончательный.ГП-211
A38: =A37+1 -> 29 | B38: Лещенко В.А. | C38: ООО "АЛЮМИНИУМ" | D38: Счет № 385 от 03.09.2025 | E38: .386200 | F38: Оплата за алюмииевые конструкции по дог.№ФП-28052024 от 28.05.2025 | G38: Бюджет | H38: Да | I38: ГП 291. Витражи.
A39: =A38+1 -> 30 | B39: Синицына В.В. | C39: ИП Никулов А.В. | D39: Счет №113 от 21.11.2025 | E39: .=146016/2 | F39: Аванс по Приложению 1/14 к Договору №ФП-10660-98 от 04.04.2025 | G39: Бюджет | I39: Монтаж системы полива на придомовой ГП 273, 280
A40: =A39+1 -> 31 | B40: Лещенко В.А. | C40: ИП Стрельцов В.А. | D40: Счет № 23 от 07.11.2025 | E40: .600050 | F40: Устройство приточно-вытяжной вентиляции согласно Приложения №1/13 от 11.06.2025г. к Договору подряда №ФП-10660-53/01 от 08.10.2024 г. | G40: Бюджет | H40: Да | I40: ГП 291. Вентиляция
A41: =A40+1 -> 32 | B41: Малый П.А. | C41: ИП Алты-Садых С.Ю | D41: Счёт№18/2 от 15.12.2025 | E41: .109250 | F41: Окончательный платеж за работы, изготовление,монтаж,шлифовку пропитку и окраску деревянных элементов террасы | G41: Бюджет | H41: да | I41: ГП-148 Дог№-ФП-10660-31 ОТ 14.11.2022
A42: =A41+1 -> 33 | B42: Малый П.А. | C42: ИП Чеботарев А.В. | D42: Счет № 1369 от 11.09.2025 | E42: .107000 | F42: Разработка дизайн проекта. Пр.№ 1/2 к дог.№ФП-10660-101 от 21.08.2025 | G42: Бюджет | H42: Да | I42: ГП 146
...

Sheet 20
E1: _____________________________ Согласовано
C2: ='19'!C2+1 -> 46101 | F2: Реестр разбит по Юр. лицам!!! КРУТИТЕ ВНИЗ
A4: ФАБРИКА ПРОЕКТОВ | E4: =SUM(E5:E6) -> 1013342.2 | F4: Реестр закрыт!!!
A5: Счет Альфа 1674 | E5: 1011661.5
A6: счет СБЕР 6989 | E6: 1680.64
A8: № п/п | B8: Инициатор платежа | C8: Контрагент - Получатель | D8: Договор/Счет | E8: Сумма к оплате | F8: Назначение платежа | G8: Бюджет/Статья | H8: Наличие Договора | I8: Примечание | J8: Отметка об оплате | K8: Спец. Распоряжение / Приоритет
B9: Коммерческая деятельность (Закупка ТМЦ Снабжение / Логистика / Транзит)
A10: 1
A11: 2
A12: 3
A13: 4
A14: 5
A15: 6
A16: 7
A17: 8
A18: 9
A19: 10
A20: 11
A21: 12
... A59: 50
B60: АХР (Продажи / IT служба / Юр служба / ФЭО /Секретариат)
A61: 1
A62: 2
A63: 3
A64: 4
A65: 5
B66: Бухгалтерия (Налоги / ЗП / ЕСН / прочие платежи бух. службы)
A67: 1
A68: 2
A69: 3
A70: 4
A71: 5
A72: ИТОГО ФАБРИКА ПРОЕКТОВ РАСХОДЫ ПО РЕЕСТРУ | E72: =SUM(E9:E71) -> 0
A73: ДЕФИЦИТ / ПРОФИЦИТ с Остатка на начало дня | E73: =E4-E72 -> 1013342.2

Sheet 21
E1: _____________________________ Согласовано
C2: ='20'!C2+1 -> 46102 | F2: Реестр разбит по Юр. лицам!!! КРУТИТЕ ВНИЗ
A4: ФАБРИКА ПРОЕКТОВ | E4: =SUM(E5:E6) -> 0
A5: Счет Альфа 1674
A6: счет СБЕР 6989
A8: № п/п | B8: Инициатор платежа | C8: Контрагент - Получатель | D8: Договор/Счет | E8: Сумма к оплате | F8: Назначение платежа | G8: Бюджет/Статья | H8: Наличие Договора | I8: Примечание | J8: Отметка об оплате | K8: Спец. Распоряжение / Приоритет
B9: Коммерческая деятельность (Закупка ТМЦ Снабжение / Логистика / Транзит)
A10: 1
A11: 2
A12: 3
A13: 4
A14: 5
A15: 6
A16: 7
A17: 8
A18: 9
A19: 10
A20: 11
A21: 12
... A59: 50
B60: АХР (Продажи / IT служба / Юр служба / ФЭО /Секретариат)
A61: 1
A62: 2
A63: 3
A64: 4
A65: 5
B66: Бухгалтерия (Налоги / ЗП / ЕСН / прочие платежи бух. службы)
A67: 1
A68: 2
A69: 3
A70: 4
A71: 5
A72: ИТОГО ФАБРИКА ПРОЕКТОВ РАСХОДЫ ПО РЕЕСТРУ | E72: =SUM(E9:E71) -> 0
A73: ДЕФИЦИТ / ПРОФИЦИТ с Остатка на начало дня | E73: =E4-E72 -> 0

Sheet 22
E1: _____________________________ Согласовано
C2: ='21'!C2+1 -> 46103 | F2: Реестр разбит по Юр. лицам!!! КРУТИТЕ ВНИЗ
A4: ФАБРИКА ПРОЕКТОВ | E4: =SUM(E5:E6) -> 0
A5: Счет Альфа 1674
A6: счет СБЕР 6989
A8: № п/п | B8: Инициатор платежа | C8: Контрагент - Получатель | D8: Договор/Счет | E8: Сумма к оплате | F8: Назначение платежа | G8: Бюджет/Статья | H8: Наличие Договора | I8: Примечание | J8: Отметка об оплате | K8: Спец. Распоряжение / Приоритет
B9: Коммерческая деятельность (Закупка ТМЦ Снабжение / Логистика / Транзит)
A10: 1
A11: 2
A12: 3
A13: 4
A14: 5
A15: 6
A16: 7
A17: 8
A18: 9
A19: 10
A20: 11
A21: 12
... A59: 50
B60: АХР (Продажи / IT служба / Юр служба / ФЭО /Секретариат)
A61: 1
A62: 2
A63: 3
A64: 4
A65: 5
B66: Бухгалтерия (Налоги / ЗП / ЕСН / прочие платежи бух. службы)
A67: 1
A68: 2
A69: 3
A70: 4
A71: 5
A72: ИТОГО ФАБРИКА ПРОЕКТОВ РАСХОДЫ ПО РЕЕСТРУ | E72: =SUM(E9:E71) -> 0
A73: ДЕФИЦИТ / ПРОФИЦИТ с Остатка на начало дня | E73: =E4-E72 -> 0

Sheet 23
E1: _____________________________ Согласовано
C2: ='22'!C2+1 -> 46104 | F2: Реестр разбит по Юр. лицам!!! КРУТИТЕ ВНИЗ
A4: ФАБРИКА ПРОЕКТОВ | E4: =SUM(E5:E6) -> 1060168.2 | F4: Реестр закрыт!!!
A5: Счет Альфа 1674 | E5: 1049561.5
A6: счет СБЕР 6989 | E6: 10606.64
A8: № п/п | B8: Инициатор платежа | C8: Контрагент - Получатель | D8: Договор/Счет | E8: Сумма к оплате | F8: Назначение платежа | G8: Бюджет/Статья | H8: Наличие Договора | I8: Примечание | J8: Отметка об оплате | K8: Спец. Распоряжение / Приоритет
B9: Коммерческая деятельность (Закупка ТМЦ Снабжение / Логистика / Транзит)
A10: 1
A11: 2
A12: 3
A13: 4
A14: 5
A15: 6
A16: 7
A17: 8
A18: 9
A19: 10
A20: 11
A21: 12
... A59: 50
B60: АХР (Продажи / IT служба / Юр служба / ФЭО /Секретариат)
A61: 1
A62: 2
A63: 3
A64: 4
A65: 5
B66: Бухгалтерия (Налоги / ЗП / ЕСН / прочие платежи бух. службы)
A67: 1
A68: 2
A69: 3
A70: 4
A71: 5
A72: ИТОГО ФАБРИКА ПРОЕКТОВ РАСХОДЫ ПО РЕЕСТРУ | E72: =SUM(E9:E71) -> 0
A73: ДЕФИЦИТ / ПРОФИЦИТ с Остатка на начало дня | E73: =E4-E72 -> 1060168.2

Sheet 24
E1: _____________________________ Согласовано
C2: ='23'!C2+1 -> 46105 | F2: Реестр разбит по Юр. лицам!!! КРУТИТЕ ВНИЗ
A4: ФАБРИКА ПРОЕКТОВ | E4: =SUM(E5:E6) -> 1098278.2 | F4: Реестр закрыт!!!
A5: Счет Альфа 1674 | E5: 1087671.5
A6: счет СБЕР 6989 | E6: 10606.64
A8: № п/п | B8: Инициатор платежа | C8: Контрагент - Получатель | D8: Договор/Счет | E8: Сумма к оплате | F8: Назначение платежа | G8: Бюджет/Статья | H8: Наличие Договора | I8: Примечание | J8: Отметка об оплате | K8: Спец. Распоряжение / Приоритет
B9: Коммерческая деятельность (Закупка ТМЦ Снабжение / Логистика / Транзит)
A10: 1 | B10: Лещенко В.А. | C10: ООО ГЕРМЕС | D10: Счет № 493 от 24.10.2025 | E10: .218750 | F10: Закупка бетона | G10: Бюджет | H10: Да | I10: ГП 294 Забор. ИП Малый. Договор №ФП31072025 от 31.07.2025 Приложение №2
A11: =A10+1 -> 2 | B11: Лещенко В.А. | C11: ООО "Айрон" | D11: Счет №АИПП-2504 от 21.03.2025 | E11: .=16534 | F11: Закупка металла. | G11: Бюджет | H11: Да | I11: (Щепкино. СПА.стены)ИП Малый Договор подряда №ФП-03022025 от 03.02.2025 Пр. №2 от 03.02.2025 ИП Малый
A12: =A11+1 -> 3 | B12: Лещенко В.А. | C12: ООО "Айрон" | D12: Счет № АИПП-3664 от 25.04.2025 | E12: .126845 | F12: Закупка металла на объект | G12: Бюджет | H12: Да | I12: ГП 204 (Навес) Договор подряда №ФП-27032025 от 27.03.2025 Приложение № 2 от 27.03.2025
A13: =A12+1 -> 4 | B13: Лещенко В.А. | C13: ООО "Айрон" | D13: Счет № АИПП-3754 от 29.04.2025 | E13: .27325 | F13: Закупка металла. | G13: Бюджет | H13: Да | I13: ГП 204(навес) Договор подряда №ФП-27032025 от 27.03.2025 Приложение №2 от 27.03.2025
A14: =A13+1 -> 5 | B14: Лещенко В.А. | C14: ООО "Айрон" | D14: Счет № АИПП-5404 от 30.06.2025 | E14: .150100 | F14: Закупка металла на объект | G14: Бюджет | H14: Да | I14: ГП 294. ХБП ИП Малый Договор подряда №ФП-19062025 от 19.06.2025 Приложение №2 от 19.06.2025
A15: =A14+1 -> 6 | B15: Лещенко В.А. | C15: ООО "Айрон" | D15: Счет № АИПП-5407 от 30.06.2025 | E15: .17300 | F15: Закупка металла на объект | G15: Бюджет | H15: Да | I15: ГП 204. ИП Малый. Договор подряда №ФП-27032025 от 27.03.2025 Приложение №2 от 27.03.2025
A16: =A15+1 -> 7 | B16: Лещенко В.А. | C16: ООО "Айрон" | D16: Счет № АИПП-5408 от 30.06.2025 | E16: .35505 | F16: Закупка металла на объект | G16: Бюджет | H16: Да | I16: ГП 13. (ХБП) ИП Малый. Договор подряда №ФП-10660-72/01 от 12.02.2024 г. Приложение №1/8 от 14.03.2025
A17: =A16+1 -> 8 | B17: Лещенко В.А. | C17: ООО "Айрон" | D17: Счет № АИПП-6301 от 04.08.2025 | E17: .163370 | F17: Закупка металла на объект | G17: Бюджет | H17: Да | I17: ГП 326. Забор ИП Малый
A18: =A17+1 -> 9 | B18: Лещенко В.А. | C18: ООО "Айрон" | D18: Счет № АИПП-6303 от 04.08.2025 | E18: .115500 | F18: Закупка металла на объект | G18: Бюджет | H18: Да | I18: ГП 294. Бассеин ИП Малый
A19: =A18+1 -> 10 | B19: Лещенко В.А. | C19: ООО "Айрон" | D19: Счет № АИПП-6304 от 04.08.2025 | E19: .51000 | F19: Закупка металла на объект | G19: Бюджет | H19: Да | I19: ГП 294. Забор ИП Малый
A20: =A19+1 -> 11 | B20: Лещенко В.А. | C20: ИП Полежаев А.А. | D20: Счет № 42 от 26.09.2025 | E20: .363298 | F20: Устройство фасада с молдингами на ХБП по дог.№ФП-10660-29 от 16.09.2022, пр.№ 1/19 | G20: Бюджет | H20: Да | I20: Окончательный ГП 326
A21: =A20+1 -> 12 | B21: Лещенко В.А. | C21: ИП Полежаев А.А. | D21: Счет № 44 от 30.09.2025 | E21: .313500 | F21: Устройство фасада с молдингами на ХБП. Договор подряда №ФП-10660-29 от 16.09.2022 Приложение № 1/25 | G21: Бюджет | H21: Да | I21: Аванс ГП 294,295
A22: =A21+1 -> 13 | B22: Малый П.А. | C22: ИП Полежаев А.А. | D22: Счёт №50 от 26.11.2025 | E22: .538264 | F22: Устройство фасада с молдингами | G22: Бюджет | H22: Да | I22: Окончательный ГП-243
A23: =A22+1 -> 14 | B23: Малый П.А. | C23: ИП Полежаев А.А. | D23: Счёт№51 от 02.12.2025 | E23: .54956 | F23: Устройство калон террасы | G23: Бюджет | H23: Да | I23: Окончательный. ГП-294.295 Договор подряда№ФП-10660-29 ОТ 16.09.2022
A24: =A23+1 -> 15 | B24: Малый П.А. | C24: ИП Полежаев А.А. | D24: Счёт№53 от 20.01.2025 | E24: .842553 | F24: Фасад | H24: Да | I24: ГП-148 Дог№-ФП-25112024-01от 25.11.2024 ПР№2 от 25.11.2024
A25: =A24+1 -> 16 | B25: Лещенко В.А. | C25: ИП Любомирский В.Г. | D25: Счет № 20 от 28.07.2025 | E25: .558077 | F25: Электромонтажные работы | G25: Бюджет | H25: Да | I25: Вн. рынок. Щепкин СПА
A26: =A25+1 -> 17 | B26: Лещенко В.А. | C26: ИП Любомирский В.Г. | D26: Счет № 25 от 23.09.2025 | E26: .210906 | F26: Оплата работ по пр.1/12 от 22.09.25 к дог.№ФП-10660-10/01 от 19.03.2024г | G26: Бюджет | H26: Да | I26: ГП 13. Электрика. 4й этап
A27: =A26+1 -> 18 | B27: Малый П.А. | C27: ИП Кравченко К.Н. | D27: Счёт№542 от 24.10.2025 | E27: .32621,5 | F27: Пиломатериалы | G27: Бюджет | H27: Да | I27: Вн.Рынок. Щепкино, кровля
A28: =A27+1 -> 19 | B28: Малый П.А. | C28: ИП Кравченко К.Н. | D28: Счёт №548 от 28.10.2025 | E28: .38400 | F28: Пиломатериалы | G28: Бюджет | H28: Да | I28: Вн.Рынок. Щепкино,кровля
A29: =A28+1 -> 20 | B29: Малый П.А. | C29: ИП Кравченко К.Н. | D29: Счёт №566 от 19.11.2025 | E29: .38400 | F29: Пиломатериалы | G29: Бюджет | H29: Да | I29: Навес ГП 262
A30: =A29+1 -> 21 | B30: Малый П.А. | C30: ИП Кравченко К.Н. | D30: Счёт № 609 от 22.12.2025 | E30: .128725,35 | F30: Пиломатериалы | G30: Бюджет | H30: Да | I30: Навес ГП 262
A31: =A30+1 -> 22 | B31: Синицына В.В. | C31: ИП Храмова Э.Э. | D31: Счет №2042 от 17.11.2025 | E31: .42000 | F31: Услуги по благоустройству территории с 10.11.2025 по 13.11.2025 | G31: Бюджет | H31: Да
A32: =A31+1 -> 23 | B32: Малый П.А. | C32: ИП Храмова Э.Э | D32: Счёт№2177от 08.12.2025 | E32: .16800 | F32: Благоустройство территории | G32: Бюджет | H32: Да | I32: ГП-103 Дог№ФП-10660-36 Планирование грунта
A33: =A32+1 -> 24 | B33: Малый П.А. | C33: ИП Храмова Э.Э. | D33: Счёт№2233 от 15.12.2025 | E33: .8400 | F33: Благоустройство территории | G33: Бюджет | H33: Да | I33: ГП-218,231,213,214,216,221,188 Дог№10660-36 от 15.032023 чистка преддомовых территорий
A34: =A33+1 -> 25 | B34: Синицына В.В. | C34: ИП Храмова Э.Э. | D34: Счет №2252 от 22.12.2025 | E34: .42000 | F34: Услуги по благоустройству территории | G34: Бюджет | H34: Да
A35: =A34+1 -> 26 | B35: Синицына В.В. | C35: ИП Храмова Э.Э. | D35: Счет №2301 от 25.12.2025г. | E35: .25200 | F35: Услуги по благоустройству территории | G35: Бюджет | H35: Да
A36: =A35+1 -> 27 | B36: Лещенко В.А. | C36: ИП Сердечная О.Ю. | D36: Счет № 291 от 17.09.2025 | E36: .59500 | F36: Договор №3 от 30.03.2022 г. Транспортные услуги по перевозке опалубки, 05.09.2025 г.,16.09.2025 г. | G36: Бюджет | H36: Да | I36: ГП 294. Бассейн.ИП Малый
A37: =A36+1 -> 28 | B37: Лещенко В.А. | C37: ИП Козлова Н.В. | D37: Счет № 27 от 19.11.2024 | E37: .=30500 | F37: Ус-во фасада по дог.№ФП-10660-93 от 01.10.2024 от 19.11.2024 | G37: Бюджет | H37: Да | I37: Окончательный.ГП-211
A38: =A37+1 -> 29 | B38: Лещенко В.А. | C38: ООО "АЛЮМИНИУМ" | D38: Счет № 385 от 03.09.2025 | E38: .386200 | F38: Оплата за алюмииевые конструкции по дог.№ФП-28052024 от 28.05.2025 | G38: Бюджет | H38: Да | I38: ГП 291. Витражи.
A39: =A38+1 -> 30 | B39: Синицына В.В. | C39: ИП Никулов А.В. | D39: Счет №113 от 21.11.2025 | E39: .=146016/2 | F39: Аванс по Приложению 1/14 к Договору №ФП-10660-98 от 04.04.2025 | G39: Бюджет | H39: Да | I39: Монтаж системы полива на придомовой ГП 273, 280
