Workbook
Name ДаНет: Тех.Лист!$A$1:$A$2
Name С2: '01'!$C$2
Name число: '01'!$C$2

Sheet 01
C2: 46082
A4: ООО ТД РТПЗ | E4: =SUM(E5:E12) -> 0
A5: Волжский счёт СБ 7503
A6: Головной счёт СБ 13291
A7: ИП Коваленко СБ 17500
A8: счёт ЦМР Банк
A9: счёт РОСБАНК 1115
A10: счёт Райффайзенбанк 38867
A11: счёт Промсвязьбанк 5439
A12: счёт Альфа-Банк 10329
A14: № п/п | B14: Инициатор платежа | C14: Контрагент - Получатель | D14: Договор/Счет | E14: Сумма к оплате | F14: Назначение платежа | G14: Подразделение - плательщик | H14: Бюджет/Статья | I14: Наличие Договора | J14: Примечание | K14: Отметка об оплате | L14: Спец. Распоряжение
B15: Коммерческий отдел (ПОСТАВЩИКИ / ПОКУПАТЕЛИ)
A16: 1
A17: 2
A18: 3
A19: 4
A20: 5
A21: 6
A22: 7
A23: 8
A24: 9
A25: 10
A26: 11
A27: 12
... A35: 20
B36: Коммерческий отдел (ЛОГИСТИКА / Хранение / ПРР)
A37: 1
A38: 2
A39: 3
A40: 4
A41: 5
A42: 6
A43: 7
A44: 8
A45: 9
A46: 10
A47: 11
A48: 12
... A56: 20
B57: ПРОИЗВОДСТВЕННЫЙ комплекс / ТЕХ служба
...

Sheet 02
C2: =С2+1 -> 46083
A4: ООО ТД РТПЗ | E4: =SUM(E5:E12) -> 11618486 | F4: РЕЕСТР ЗАКРЫТ !!!
A5: Волжский счёт СБ 7503 | E5: 3979050.6
A6: Головной счёт СБ 13291 | E6: 2919755.7
A7: ИП Коваленко СБ 17500
A8: счёт ЦМР Банк | E8: 15821.6
A9: счёт РОСБАНК 1115 | E9: 5166.84
A10: счёт Райффайзенбанк 38867 | E10: 32595.97
A11: счёт Промсвязьбанк 5439 | E11: 2961193.6
A12: счёт Альфа-Банк 10329 | E12: 1704901.4
A14: № п/п | B14: Инициатор платежа | C14: Контрагент - Получатель | D14: Договор/Счет | E14: Сумма к оплате | F14: Назначение платежа | G14: Подразделение - плательщик | H14: Бюджет/Статья | I14: Наличие Договора | J14: Примечание | K14: Отметка об оплате | L14: Спец. Распоряжение
B15: Коммерческий отдел (ПОСТАВЩИКИ / ПОКУПАТЕЛИ)
A16: 1 | B16: Дынник | C16: ООО "Группа Компаний Демидов" | D16: СЧЕТ № ФИЛ26-428364 от 27.02.26 | E16: 35258 | F16: Труба профильная (2 сорт) (некондиция, упаковка) | G16: РТПЗ Волжский | H16: Бюджет ПЛАН | I16: Да | K16: оплачен
A17: 2 | B17: Дынник | C17: ООО "Группа Компаний Демидов" | D17: СЧЕТ № ФИЛ26-428102 от 27.02.26 | E17: 155154 | F17: Труба профильная (2 сорт) (некондиция, упаковка) | G17: РТПЗ Волжский | H17: Бюджет ПЛАН | I17: Да | K17: оплачен
A18: 3
A19: 4 | B19: Федоров А.А. | C19: Северсталь ПАО | D19: Договр № 643/1000-24100303 от 12.04.2024 | E19: .26000000 | F19: Металлопрокат | I19: Да
A20: 5 | B20: Крикса М.П. | C20: АЛЮМИНАРТ ООО | D20: Договор № 14 от 21.01.2026 г | E20: 3404096 | F20: возврат ошибочно перечисленных д.с | G20: РТПЗ Волжский | I20: Да | J20: Согласовано Солодовниковым А.Н. | K20: оплачен
A21: 6
A22: 7
A23: 8
A24: 9
A25: 10
A26: 11
A27: 12
A28: 13
A29: 14
A30: 15
A31: 16
A32: 17
... A35: 20
B36: Коммерческий отдел (ЛОГИСТИКА / Хранение / ПРР)
A37: 1 | B37: Голка | C37: АК№2 ООО | D37: Счет №1975 от 27.01 | E37: 115000 | F37: Транспорт | G37: РТПЗ Волжский | H37: Бюджет ПЛАН | I37: Да | K37: оплачен
A38: 2 | B38: Голка | C38: Дентро ООО | D38: Счет №2528 от 29.01 | E38: 58000 | F38: Транспорт | G38: РТПЗ Волжский | H38: Бюджет ПЛАН | I38: Нет | J38: скан | K38: оплачен
A39: 3 | B39: Голка | C39: РАУТ ООО | D39: Счет №4,6,7,10 от 26.01 | E39: =55000+80000+70000+47000 -> 252000 | F39: Транспорт | G39: РТПЗ Волжский | H39: Бюджет ПЛАН | I39: Да | K39: оплачен
A40: 4 | B40: Голка | C40: Стальстройпоставка ООО | D40: Счет №4,6,7,10 от 26.01 | E40: =96000+75000 -> 171000 | F40: Транспорт | G40: РТПЗ Волжский | H40: Бюджет ПЛАН | I40: Нет | J40: копия | K40: оплачен
A41: 5 | B41: Голка | C41: Кравцов С.А. ИП | D41: Счет №2 от 30.01 | E41: 20000 | F41: Транспорт | G41: РТПЗ Волжский | H41: Бюджет ПЛАН | I41: Нет | K41: оплачен
A42: 6 | B42: Голка | C42: НЕО ТРАНС ООО | D42: Счет №813 от 25.01 | E42: 85000 | F42: Транспорт | G42: РТПЗ Волжский | H42: Бюджет ПЛАН | I42: Да | K42: оплачен
A43: 7 | B43: Голка | C43: Черненко-Рус ООО | D43: Счет чр457-608п от 25.08 | E43: 95000 | F43: Транспорт | G43: РТПЗ Волжский | H43: Бюджет ПЛАН | I43: Да | K43: оплачен
A44: 8
A45: 9
...

Sheet 03
C2: ='02'!C2+1 -> 46084
A4: ООО ТД РТПЗ | E4: =SUM(E5:E12) -> 9256753.5 | F4: РЕЕСТР ЗАКРЫТ !!!
A5: Волжский счёт СБ 7503 | E5: 9081635.9
A6: Головной счёт СБ 13291 | E6: 19755.66
A8: счёт ЦМР Банк | E8: 15821.6
A9: счёт РОСБАНК 1115 | E9: 3366.84
A10: счёт Райффайзенбанк 38867 | E10: 120078.47
A11: счёт Промсвязьбанк 5439 | E11: 11193.59
A12: счёт Альфа-Банк 10329 | E12: 4901.43
A14: № п/п | B14: Инициатор платежа | C14: Контрагент - Получатель | D14: Договор/Счет | E14: Сумма к оплате | F14: Назначение платежа | G14: Подразделение - плательщик | H14: Бюджет/Статья | I14: Наличие Договора | J14: Примечание | K14: Отметка об оплате | L14: Спец. Распоряжение
B15: Коммерческий отдел (ПОСТАВЩИКИ / ПОКУПАТЕЛИ)
A16: 1
A17: 2 | B17: Федоров А.А. | C17: Северсталь ПАО | D17: Договр № 643/1000-24100303 от 12.04.2024 | E17: 26000000 | F17: Металлопрокат
A18: 3 | B18: Федоров А.А. | C18: НЛМК ПАО | D18: Договор В204709-24 от 24.10.2024 | E18: 4652500.6 | F18: Металлопрокат
A19: 4
A20: 5
A21: 6
A22: 7
A23: 8
A24: 9
A25: 10
A26: 11
A27: 12
A28: 13
A29: 14
A30: 15
... A35: 20
B36: Коммерческий отдел (ЛОГИСТИКА / Хранение / ПРР)
A37: 1
A38: 2
A39: 3
A40: 4
A41: 5
A42: 6
A43: 7
A44: 8
A45: 9
A46: 10
A47: 11
A48: 12
...

Sheet 04
C2: ='03'!C2+1 -> 46085
A4: ООО ТД РТПЗ | E4: =SUM(E5:E12) -> 5862223.4 | F4: РЕЕСТР ЗАКРЫТ !!!
A5: Волжский счёт СБ 7503 | E5: 5656225.8 | F5: =E37+E38+E39+E40+E41+E42+E43+E44+E45++E46+E47+E48+E58+E59+E61+E62+E63+E67+E69+E70+E74+E76+E77+E78+E79+E80+E81+E82+E83+E89+E90+E91+E92+E93+E94+E95+E105 -> 3121479.9
A6: Головной счёт СБ 13291 | E6: 19755.66
A7: ИП Коваленко СБ 17500
A8: счёт ЦМР Банк | E8: 15821.6
A9: счёт РОСБАНК 1115 | E9: 3366.84
A10: счёт Райффайзенбанк 38867 | E10: 120078.47
A11: счёт Промсвязьбанк 5439 | E11: 42073.59
A12: счёт Альфа-Банк 10329 | E12: 4901.43
A14: № п/п | B14: Инициатор платежа | C14: Контрагент - Получатель | D14: Договор/Счет | E14: Сумма к оплате | F14: Назначение платежа | G14: Подразделение - плательщик | H14: Бюджет/Статья | I14: Наличие Договора | J14: Примечание | K14: Отметка об оплате | L14: Спец. Распоряжение
B15: Коммерческий отдел (ПОСТАВЩИКИ / ПОКУПАТЕЛИ)
A16: 1
A17: 2 | B17: Федоров А.А. | C17: Северсталь ПАО | D17: Договр № 643/1000-24100303 от 12.04.2024 | E17: 26000000 | F17: Металлопрокат | I17: Да
A18: 3 | B18: Федоров А.А. | C18: НЛМК ПАО | D18: Договор В204709-24 от 24.10.2024 | E18: 4652500.6 | F18: Металлопрокат | I18: Да
A19: 4
A20: 5
A21: 6
A22: 7
A23: 8
A24: 9
A25: 10
A26: 11
A27: 12
A28: 13
A29: 14
A30: 15
... A35: 20
B36: Коммерческий отдел (ЛОГИСТИКА / Хранение / ПРР)
A37: 1 | B37: Голка | C37: Ушаков ИП | D37: Счет № 55,50 от 02.02 | E37: =80000+80000 -> 160000 | F37: Транспорт | G37: РТПЗ Волжский | H37: Бюджет ПЛАН | I37: Нет | J37: скан | K37: оплачен
A38: 2 | B38: Голка | C38: Донцов ИП | D38: Счет №03 от 13.02 | E38: 58500 | F38: Транспорт | G38: РТПЗ Волжский | H38: Бюджет ПЛАН | I38: Нет | J38: копия | K38: оплачен
A39: 3 | B39: Голка | C39: Альфа ООО | D39: Счет №5 от 27.02 | E39: 105000 | F39: Транспорт | G39: РТПЗ Волжский | H39: Бюджет ПЛАН | I39: Да | K39: оплачен
A40: 4 | B40: Голка | C40: Воронков Ю.С. ИП | D40: Счет №7.26 от 15.01 | E40: 58000 | F40: Транспорт | G40: РТПЗ Волжский | H40: Бюджет ПЛАН | I40: Нет | J40: скан | K40: оплачен
A41: 5 | B41: Голка | C41: СКС ГРУПП ООО | D41: Счет №18,24,22 от 29.01 | E41: =42000+36000+36000 -> 114000 | F41: Транспорт | G41: РТПЗ Волжский | H41: Бюджет ПЛАН | I41: Да | K41: оплачен
A42: 6 | B42: Голка | C42: Черненко-Рус ООО | D42: Счет №1772 от 21.08 | E42: 90000 | F42: Транспорт | G42: РТПЗ Волжский | H42: Бюджет ПЛАН | I42: Да | K42: оплачен
A43: 7 | B43: Голка | C43: Долотказин ИП | D43: Счет №07 от 02.02 | E43: 55000 | F43: Транспорт | G43: РТПЗ Волжский | H43: Бюджет ПЛАН | I43: Да | K43: оплачен
A44: 8 | B44: Голка | C44: Вектор-Н ООО | D44: Счет №1183 от 26.12 | E44: 95000 | F44: Транспорт | G44: РТПЗ Волжский | H44: Бюджет ПЛАН | I44: Да | K44: оплачен
A45: 9 | B45: Голка | C45: Дентро ООО | D45: Счет №3627,3628 от 03.02 | E45: =95000+90000 -> 185000 | F45: Транспорт | G45: РТПЗ Волжский | H45: Бюджет ПЛАН | I45: Нет | J45: скан | K45: оплачен
A46: 10 | B46: Голка | C46: РАУТ ООО | D46: Счет №8,9 от 02.02 | E46: =70000+58000 -> 128000 | F46: Транспорт | G46: РТПЗ Волжский | H46: Бюджет ПЛАН | I46: Да | K46: оплачен
A47: 11 | B47: Голка | C47: Кузнеченков ИП | D47: Счет №14 от 19.02 | E47: 54999.9 | F47: Транспорт | G47: РТПЗ Волжский | H47: Бюджет ПЛАН | I47: Да | K47: оплачен
...

Sheet 05
C2: ='04'!C2+1 -> 46086
A4: ООО ТД РТПЗ | E4: =SUM(E5:E12) -> 195532.14 | F4: РЕЕСТР ЗАКРЫТ !!!
A5: Волжский счёт СБ 7503 | E5: 129274.05
A6: Головной счёт СБ 13291 | E6: 19755.66
A7: ИП Коваленко СБ 17500
A8: счёт ЦМР Банк | E8: 15821.6
A9: счёт РОСБАНК 1115 | E9: 3366.84
A10: счёт Райффайзенбанк 38867 | E10: 1395.47
A11: счёт Промсвязьбанк 5439 | E11: 21017.09
A12: счёт Альфа-Банк 10329 | E12: 4901.43
A14: № п/п | B14: Инициатор платежа | C14: Контрагент - Получатель | D14: Договор/Счет | E14: Сумма к оплате | F14: Назначение платежа | G14: Подразделение - плательщик | H14: Бюджет/Статья | I14: Наличие Договора | J14: Примечание | K14: Отметка об оплате | L14: Спец. Распоряжение
B15: Коммерческий отдел (ПОСТАВЩИКИ / ПОКУПАТЕЛИ)
A16: 1
A17: 2 | B17: Федоров А.А. | C17: Северсталь ПАО | D17: Договр № 643/1000-24100303 от 12.04.2024 | E17: 26000000 | F17: Металлопрокат
A18: 3 | B18: Федоров А.А. | C18: НЛМК ПАО | D18: Договор В204709-24 от 24.10.2024 | E18: 4652500.6 | F18: Металлопрокат | K18: оплачен
A19: 4
A20: 5
A21: 6
A22: 7
A23: 8
A24: 9
A25: 10
A26: 11
A27: 12
A28: 13
A29: 14
A30: 15
... A35: 20
B36: Коммерческий отдел (ЛОГИСТИКА / Хранение / ПРР)
A37: 1
A38: 2
A39: 3
A40: 4
A41: 5
A42: 6
A43: 7
A44: 8
A45: 9
A46: 10
A47: 11
...

Sheet 06
C2: ='05'!C2+1 -> 46087
A4: ООО ТД РТПЗ | E4: =SUM(E5:E12) -> 9549260.8 | F4: РЕЕСТР ЗАКРЫТ !!!
A5: Волжский счёт СБ 7503 | E5: 9486369.6
A6: Головной счёт СБ 13291 | E6: 19755.66
A7: ИП Коваленко СБ 17500
A8: счёт ЦМР Банк | E8: 15821.6
A9: счёт РОСБАНК 1115 | E9: 0
A10: счёт Райффайзенбанк 38867 | E10: 1395.47
A11: счёт Промсвязьбанк 5439 | E11: 21017.09
A12: счёт Альфа-Банк 10329 | E12: 4901.43
A14: № п/п | B14: Инициатор платежа | C14: Контрагент - Получатель | D14: Договор/Счет | E14: Сумма к оплате | F14: Назначение платежа | G14: Подразделение - плательщик | H14: Бюджет/Статья | I14: Наличие Договора | J14: Примечание | K14: Отметка об оплате | L14: Спец. Распоряжение
B15: Коммерческий отдел (ПОСТАВЩИКИ / ПОКУПАТЕЛИ)
A16: 1
A17: 2 | B17: Федоров А.А. | C17: Северсталь ПАО | D17: Договр № 643/1000-24100303 от 12.04.2024 | E17: 26000000 | F17: Металлопрокат
A18: 3
A19: 4
A20: 5
A21: 6
A22: 7
A23: 8
A24: 9
A25: 10
A26: 11
A27: 12
A28: 13
A29: 14
... A35: 20
B36: Коммерческий отдел (ЛОГИСТИКА / Хранение / ПРР)
A37: 1
A38: 2
A39: 3
A40: 4
A41: 5
A42: 6
A43: 7
A44: 8
A45: 9
A46: 10
A47: 11
A48: 12
...

Sheet 07
C2: ='06'!C2+1 -> 46088
A4: ООО ТД РТПЗ | E4: =SUM(E5:E12) -> 0
A5: Волжский счёт СБ 7503
A6: Головной счёт СБ 13291
A7: ИП Коваленко СБ 17500
A8: счёт ЦМР Банк
A9: счёт РОСБАНК 1115
A10: счёт Райффайзенбанк 38867
A11: счёт Промсвязьбанк 5439
A12: счёт Альфа-Банк 10329
A14: № п/п | B14: Инициатор платежа | C14: Контрагент - Получатель | D14: Договор/Счет | E14: Сумма к оплате | F14: Назначение платежа | G14: Подразделение - плательщик | H14: Бюджет/Статья | I14: Наличие Договора | J14: Примечание | K14: Отметка об оплате | L14: Спец. Распоряжение
B15: Коммерческий отдел (ПОСТАВЩИКИ / ПОКУПАТЕЛИ)
A16: 1
A17: 2
A18: 3
A19: 4
A20: 5
A21: 6
A22: 7
A23: 8
A24: 9
A25: 10
A26: 11
A27: 12
... A35: 20
B36: Коммерческий отдел (ЛОГИСТИКА / Хранение / ПРР)
A37: 1
A38: 2
A39: 3
A40: 4
A41: 5
A42: 6
A43: 7
A44: 8
A45: 9
A46: 10
A47: 11
A48: 12
... A56: 20
B57: ПРОИЗВОДСТВЕННЫЙ комплекс / ТЕХ служба
...

Sheet 08
C2: ='07'!C2+1 -> 46089
A4: ООО ТД РТПЗ | E4: =SUM(E5:E12) -> 0
A5: Волжский счёт СБ 7503
A6: Головной счёт СБ 13291
A7: ИП Коваленко СБ 17500
A8: счёт ЦМР Банк
A9: счёт РОСБАНК 1115
A10: счёт Райффайзенбанк 38867
A11: счёт Промсвязьбанк 5439
A12: счёт Альфа-Банк 10329
A14: № п/п | B14: Инициатор платежа | C14: Контрагент - Получатель | D14: Договор/Счет | E14: Сумма к оплате | F14: Назначение платежа | G14: Подразделение - плательщик | H14: Бюджет/Статья | I14: Наличие Договора | J14: Примечание | K14: Отметка об оплате | L14: Спец. Распоряжение
B15: Коммерческий отдел (ПОСТАВЩИКИ / ПОКУПАТЕЛИ)
A16: 1
A17: 2
A18: 3
A19: 4
A20: 5
A21: 6
A22: 7
A23: 8
A24: 9
A25: 10
A26: 11
A27: 12
... A35: 20
B36: Коммерческий отдел (ЛОГИСТИКА / Хранение / ПРР)
A37: 1
A38: 2
A39: 3
A40: 4
A41: 5
A42: 6
A43: 7
A44: 8
A45: 9
A46: 10
A47: 11
A48: 12
... A56: 20
B57: ПРОИЗВОДСТВЕННЫЙ комплекс / ТЕХ служба
...

Sheet 09
C2: ='08'!C2+1 -> 46090
A4: ООО ТД РТПЗ | E4: =SUM(E5:E12) -> 0
A5: Волжский счёт СБ 7503
A6: Головной счёт СБ 13291
A7: ИП Коваленко СБ 17500
A8: счёт ЦМР Банк
A9: счёт РОСБАНК 1115
A10: счёт Райффайзенбанк 38867
A11: счёт Промсвязьбанк 5439
A12: счёт Альфа-Банк 10329
A14: № п/п | B14: Инициатор платежа | C14: Контрагент - Получатель | D14: Договор/Счет | E14: Сумма к оплате | F14: Назначение платежа | G14: Подразделение - плательщик | H14: Бюджет/Статья | I14: Наличие Договора | J14: Примечание | K14: Отметка об оплате | L14: Спец. Распоряжение
B15: Коммерческий отдел (ПОСТАВЩИКИ / ПОКУПАТЕЛИ)
A16: 1
A17: 2
A18: 3
A19: 4
A20: 5
A21: 6
A22: 7
A23: 8
A24: 9
A25: 10
A26: 11
A27: 12
... A35: 20
B36: Коммерческий отдел (ЛОГИСТИКА / Хранение / ПРР)
A37: 1
A38: 2
A39: 3
A40: 4
A41: 5
A42: 6
A43: 7
A44: 8
A45: 9
A46: 10
A47: 11
A48: 12
... A56: 20
B57: ПРОИЗВОДСТВЕННЫЙ комплекс / ТЕХ служба
...

Sheet 10
C2: ='09'!C2+1 -> 46091
A4: ООО ТД РТПЗ | E4: =SUM(E5:E12) -> 980754.35 | F4: РЕЕСТР ЗАКРЫТ !!!
A5: Волжский счёт СБ 7503 | E5: 917863.1
A6: Головной счёт СБ 13291 | E6: 19755.66
A7: ИП Коваленко СБ 17500
A8: счёт ЦМР Банк | E8: 15821.6
A9: счёт РОСБАНК 1115 | E9: 0
A10: счёт Райффайзенбанк 38867 | E10: 1395.47
A11: счёт Промсвязьбанк 5439 | E11: 21017.09
A12: счёт Альфа-Банк 10329 | E12: 4901.43
A14: № п/п | B14: Инициатор платежа | C14: Контрагент - Получатель | D14: Договор/Счет | E14: Сумма к оплате | F14: Назначение платежа | G14: Подразделение - плательщик | H14: Бюджет/Статья | I14: Наличие Договора | J14: Примечание | K14: Отметка об оплате | L14: Спец. Распоряжение
B15: Коммерческий отдел (ПОСТАВЩИКИ / ПОКУПАТЕЛИ)
A16: 1 | I16: Да | J16: с райффайзена
A17: 2 | B17: Федоров А.А. | C17: Северсталь ПАО | D17: Договр № 643/1000-24100303 от 12.04.2024 | E17: .26000000 | F17: Металлопрокат
A18: 3
A19: 4
A20: 5
A21: 6
A22: 7
A23: 8
A24: 9
A25: 10
A26: 11
A27: 12
A28: 13
A29: 14
... A35: 20
B36: Коммерческий отдел (ЛОГИСТИКА / Хранение / ПРР)
A37: 1
A38: 2
A39: 3
A40: 4
A41: 5
A42: 6
A43: 7
A44: 8
A45: 9
A46: 10
A47: 11
A48: 12
...

Sheet 11
C2: ='10'!C2+1 -> 46092
A4: ООО ТД РТПЗ | E4: =SUM(E5:E12) -> 1090296.2 | F4: РЕЕСТР ЗАКРЫТ !!!
A5: Волжский счёт СБ 7503 | E5: 990305.48
A6: Головной счёт СБ 13291 | E6: 19755.66
A7: ИП Коваленко СБ 17500
A8: счёт ЦМР Банк | E8: 15821.6
A9: счёт РОСБАНК 1115 | E9: 0
A10: счёт Райффайзенбанк 38867 | E10: 1395.47
A11: счёт Промсвязьбанк 5439 | E11: 21017.09
A12: счёт Альфа-Банк 10329 | E12: 42000.93
A14: № п/п | B14: Инициатор платежа | C14: Контрагент - Получатель | D14: Договор/Счет | E14: Сумма к оплате | F14: Назначение платежа | G14: Подразделение - плательщик | H14: Бюджет/Статья | I14: Наличие Договора | J14: Примечание | K14: Отметка об оплате | L14: Спец. Распоряжение
B15: Коммерческий отдел (ПОСТАВЩИКИ / ПОКУПАТЕЛИ)
A16: 1 | B16: Дынник | C16: ООО "Группа Компаний Демидов" | D16: СЧЕТ № ФИЛ26-432101 от 10.03.26 | E16: 82628 | F16: Труба профильная (2 сорт) (некондиция. упаковка) | G16: РТПЗ Волжский | I16: Да | J16: В счете не указан договор - Договор поставки №15032021/2217 от 15.03.2021 | K16: оплачен
A17: 2 | B17: Федоров А.А. | C17: Северсталь ПАО | D17: Договр № 643/1000-24100303 от 12.04.2024 | E17: .26000000 | F17: Металлопрокат | I17: Да
A18: 3
A19: 4
A20: 5
A21: 6
A22: 7
A23: 8
A24: 9
A25: 10
A26: 11
A27: 12
A28: 13
A29: 14
... A35: 20
B36: Коммерческий отдел (ЛОГИСТИКА / Хранение / ПРР)
A37: 1 | B37: Голка | C37: ТЛК-Групп ООО | D37: Счет №5906,5262,5620,5370 от 26.01 | E37: =56000+57000+65000+90000 -> 268000 | F37: Транспорт | G37: РТПЗ Волжский | H37: Бюджет | I37: Да | K37: оплачен
A38: 2 | B38: Голка | C38: Качурин М.О. ИП | D38: Счет №112,124,207 от 22.01 | E38: =60000+50000+50000 -> 160000 | F38: Транспорт | G38: РТПЗ Волжский | H38: Бюджет | I38: Да | K38: оплачен
A39: 3 | B39: Голка | C39: Дентро ООО | D39: Счет №6132,3973,6774,8155 от 04.02 | E39: =75000+75000+55000+85000 -> 290000 | F39: Транспорт | G39: РТПЗ Волжский | H39: Бюджет | I39: Да | K39: оплачен
A40: 4 | B40: Голка | C40: Промснаб ООО | D40: Счет №14 от 06.02 | E40: 58000 | F40: Транспорт | G40: РТПЗ Волжский | H40: Бюджет | I40: Да | K40: оплачен
A41: 5 | B41: Голка | C41: Ушаков А.С. ИП | D41: Счет №66 от 09.02 | E41: 80000 | F41: Транспорт | G41: РТПЗ Волжский | H41: Бюджет | I41: Да | K41: оплачен
A42: 6 | B42: Голка | C42: Стальстройпоставка ООО | D42: Счет №50,67,82,41,68,69 от 09.02 | E42: =95000+40000+130000+26000+40000+88000 -> 419000 | F42: Транспорт | G42: РТПЗ Волжский | H42: Бюджет | I42: Да | K42: оплачен
A43: 7 | B43: Голка | C43: АК №2 ООО | D43: Счет №1980 от 05.02 | E43: 120000 | F43: Транспорт | G43: РТПЗ Волжский | H43: Бюджет | I43: Да | K43: оплачен
A44: 8 | B44: Голка | C44: НЕО ТРАНС ООО | D44: Счет №1867 от 04.02 | E44: 100000 | F44: Транспорт | G44: РТПЗ Волжский | H44: Бюджет | I44: Да | K44: оплачен
A45: 9 | B45: Голка | C45: СКС-Групп ООО | D45: Счет №23 от 03.02 | E45: 40000 | F45: Транспорт | G45: РТПЗ Волжский | H45: Бюджет | I45: Да | K45: оплачен
A46: 10 | B46: Голка | C46: Настина Т.В. ИП | D46: Счет №18 от 08.02 | E46: 56000 | F46: Транспорт | G46: РТПЗ Волжский | H46: Бюджет | I46: Да | K46: оплачен
A47: 11 | B47: Голка | C47: Вектор-Н ООО | D47: Счет №1,36 от 04.02 | E47: =90000+95000 -> 185000 | F47: Транспорт | G47: РТПЗ Волжский | H47: Бюджет | I47: Да | K47: оплачен
A48: 12 | B48: Голка | C48: РАУТ ООО | D48: Счет №11 от 30.01 | E48: 98000 | F48: Транспорт | G48: РТПЗ Волжский | H48: Бюджет | I48: Да | K48: оплачен
...

Sheet 12
C2: ='11'!C2+1 -> 46093
A4: ООО ТД РТПЗ | E4: =SUM(E5:E12) -> 23890461 | F4: РЕЕСТР ЗАКРЫТ !!!
A5: Волжский счёт СБ 7503 | E5: 15778008
A6: Головной счёт СБ 13291 | E6: 19755.66
A7: ИП Коваленко СБ 17500
A8: счёт ЦМР Банк | E8: 15821.6
A9: счёт РОСБАНК 1115 | E9: 0
A10: счёт Райффайзенбанк 38867 | E10: 4585965.3
A11: счёт Промсвязьбанк 5439 | E11: 3448909
A12: счёт Альфа-Банк 10329 | E12: 42000.93
A14: № п/п | B14: Инициатор платежа | C14: Контрагент - Получатель | D14: Договор/Счет | E14: Сумма к оплате | F14: Назначение платежа | G14: Подразделение - плательщик | H14: Бюджет/Статья | I14: Наличие Договора | J14: Примечание | K14: Отметка об оплате | L14: Спец. Распоряжение
B15: Коммерческий отдел (ПОСТАВЩИКИ / ПОКУПАТЕЛИ)
A16: 1 | B16: Татевосян | C16: Ереванский завод стальных труб Металл Стиль ЗАО | D16: Письмо от 27.02.2026 | E16: 157343.24 | F16: возврат по письму | I16: Да | K16: оплачен
A17: 2 | B17: Федоров А.А. | C17: Северсталь ПАО | D17: Договр № 643/1000-24100303 от 12.04.2024 | E17: .26000000 | F17: Металлопрокат | I17: Да
A18: 3 | B18: Федоров А.А. | C18: НЛМК ПАО | D18: Договор №204709-23 от 15.03.2023 | E18: 6000000 | F18: Металлопрокат | I18: Да | K18: оплачен
A19: 4
A20: 5
A21: 6
A22: 7
A23: 8
A24: 9
A25: 10
A26: 11
A27: 12
A28: 13
A29: 14
A30: 15
... A35: 20
B36: Коммерческий отдел (ЛОГИСТИКА / Хранение / ПРР)
A37: 1
A38: 2
A39: 3
A40: 4
A41: 5
A42: 6
A43: 7
A44: 8
A45: 9
A46: 10
A47: 11
...

Sheet 13
C2: ='12'!C2+1 -> 46094
A4: ООО ТД РТПЗ | E4: =SUM(E5:E12) -> 3301667.9 | F4: РЕЕСТР ЗАКРЫТ !!!
A5: Волжский счёт СБ 7503 | E5: 3080006.4
A6: Головной счёт СБ 13291 | E6: 4429.92
A8: счёт ЦМР Банк | E8: 15821.6
A9: счёт РОСБАНК 1115 | E9: 49366.84
A10: счёт Райффайзенбанк 38867 | E10: 78553.1
A11: счёт Промсвязьбанк 5439 | E11: 31489.09
A12: счёт Альфа-Банк 10329 | E12: 42000.93
A14: № п/п | B14: Инициатор платежа | C14: Контрагент - Получатель | D14: Договор/Счет | E14: Сумма к оплате | F14: Назначение платежа | G14: Подразделение - плательщик | H14: Бюджет/Статья | I14: Наличие Договора | J14: Примечание | K14: Отметка об оплате | L14: Спец. Распоряжение
B15: Коммерческий отдел (ПОСТАВЩИКИ / ПОКУПАТЕЛИ)
A16: 1
A17: 2 | B17: Федоров А.А. | C17: Северсталь ПАО | D17: Договр № 643/1000-24100303 от 12.04.2024 | E17: .25 933 135,75 | F17: Металлопрокат
A18: 3
A19: 4
A20: 5
A21: 6
A22: 7
A23: 8
A24: 9
A25: 10
A26: 11
A27: 12
A28: 13
A29: 14
... A35: 20
B36: Коммерческий отдел (ЛОГИСТИКА / Хранение / ПРР)
A37: 1
A38: 2
A39: 3
A40: 4
A41: 5
A42: 6
A43: 7
A44: 8
A45: 9
A46: 10
A47: 11
A48: 12
... A56: 20
...

Sheet 14
C2: ='13'!C2+1 -> 46095
A4: ООО ТД РТПЗ | E4: =SUM(E5:E12) -> 0
A5: Волжский счёт СБ 7503
A6: Головной счёт СБ 13291
A7: ИП Коваленко СБ 17500
A8: счёт ЦМР Банк
A9: счёт РОСБАНК 1115
A10: счёт Райффайзенбанк 38867
A11: счёт Промсвязьбанк 5439
A12: счёт Альфа-Банк 10329
A14: № п/п | B14: Инициатор платежа | C14: Контрагент - Получатель | D14: Договор/Счет | E14: Сумма к оплате | F14: Назначение платежа | G14: Подразделение - плательщик | H14: Бюджет/Статья | I14: Наличие Договора | J14: Примечание | K14: Отметка об оплате | L14: Спец. Распоряжение
B15: Коммерческий отдел (ПОСТАВЩИКИ / ПОКУПАТЕЛИ)
A16: 1
A17: 2
A18: 3
A19: 4
A20: 5
A21: 6
A22: 7
A23: 8
A24: 9
A25: 10
A26: 11
A27: 12
... A35: 20
B36: Коммерческий отдел (ЛОГИСТИКА / Хранение / ПРР)
A37: 1
A38: 2
A39: 3
A40: 4
A41: 5
A42: 6
A43: 7
A44: 8
A45: 9
A46: 10
A47: 11
A48: 12
... A56: 20
B57: ПРОИЗВОДСТВЕННЫЙ комплекс / ТЕХ служба
...

Sheet 15
C2: ='14'!C2+1 -> 46096
A4: ООО ТД РТПЗ | E4: =SUM(E5:E12) -> 0
A5: Волжский счёт СБ 7503
A6: Головной счёт СБ 13291
A7: ИП Коваленко СБ 17500
A8: счёт ЦМР Банк
A9: счёт РОСБАНК 1115
A10: счёт Райффайзенбанк 38867
A11: счёт Промсвязьбанк 5439
A12: счёт Альфа-Банк 10329
A14: № п/п | B14: Инициатор платежа | C14: Контрагент - Получатель | D14: Договор/Счет | E14: Сумма к оплате | F14: Назначение платежа | G14: Подразделение - плательщик | H14: Бюджет/Статья | I14: Наличие Договора | J14: Примечание | K14: Отметка об оплате | L14: Спец. Распоряжение
B15: Коммерческий отдел (ПОСТАВЩИКИ / ПОКУПАТЕЛИ)
A16: 1
A17: 2
A18: 3
A19: 4
A20: 5
A21: 6
A22: 7
A23: 8
A24: 9
A25: 10
A26: 11
A27: 12
... A35: 20
B36: Коммерческий отдел (ЛОГИСТИКА / Хранение / ПРР)
A37: 1
A38: 2
A39: 3
A40: 4
A41: 5
A42: 6
A43: 7
A44: 8
A45: 9
A46: 10
A47: 11
A48: 12
... A56: 20
B57: ПРОИЗВОДСТВЕННЫЙ комплекс / ТЕХ служба
...

Sheet 16
C2: ='15'!C2+1 -> 46097
A4: ООО ТД РТПЗ | E4: =SUM(E5:E12) -> 35745078 | F4: РЕЕСТР ЗАКРЫТ !!!
A5: Волжский счёт СБ 7503 | E5: 35026273 | F5: =E19+E20+E37+E39+E40+E41+E42+E43+E44+E45+E46+E47+E48+E49+E50+E58+E59+E60+E61+E62+E63+E64+E65+E66+E67+E68+E69+E70+E71+E72+E73+E74+E75+E76+E77+E78+E79+E87+E88+E89+E90+E91+E114 -> 2549995.9
A6: Головной счёт СБ 13291 | E6: 4429.92
A7: ИП Коваленко СБ 17500
A8: счёт ЦМР Банк | E8: 15821.6
A9: счёт РОСБАНК 1115 | E9: 49366.84
A10: счёт Райффайзенбанк 38867 | E10: 574893.1
A11: счёт Промсвязьбанк 5439 | E11: 31489.09
A12: счёт Альфа-Банк 10329 | E12: 42803.93
A14: № п/п | B14: Инициатор платежа | C14: Контрагент - Получатель | D14: Договор/Счет | E14: Сумма к оплате | F14: Назначение платежа | G14: Подразделение - плательщик | H14: Бюджет/Статья | I14: Наличие Договора | J14: Примечание | K14: Отметка об оплате | L14: Спец. Распоряжение
B15: Коммерческий отдел (ПОСТАВЩИКИ / ПОКУПАТЕЛИ)
A16: 1 | B16: пышный | C16: Кармет | E16: 3000000 | I16: Да | J16: с райфа | K16: оплачен
A17: 2 | B17: Федоров А.А. | C17: Северсталь ПАО | D17: Договр № 643/1000-24100303 от 12.04.2024 | E17: .25 933 135,75 | F17: Металлопрокат | I17: Да
A18: 3 | B18: Федоров А.А. | C18: НЛМК ПАО | D18: Договор №204709-23 от 15.03.2023 | E18: 3000000 | F18: Металлопрокат | I18: Да
A19: 4 | B19: Крикса М.П. | C19: АлСар ТОО | D19: Контракт № 19Э-2024 от 16.08.2024 | E19: 333474.3 | F19: Возврат денежных средств клиенту. | G19: РТПЗ Волжский | I19: Да | J19: Согласовано с Солодовниковым А.Н. | K19: оплачен
A20: 5 | B20: Дынник | C20: ООО "Группа Компаний Демидов" | D20: СЧЕТ № ФИЛ26-434576 от 13.03.26 | E20: 35592.6 | F20: Труба профильная 2 сорт (некондиция, упаковка) | G20: РТПЗ Волжский | I20: Да
A21: 6
A22: 7 | B22: Ченский М.В. | C22: СтройПартнёр ООО | D22: Договор №СП23-00689-КР от 12.07.2023 | E22: 671152.5 | F22: Металлопрокат | I22: Да
A23: 8 | B23: Ченский М.В. | C23: Мечел-Сервис ООО | D23: Договор №370019010049 от 01.04.2019 | E23: 263219.23 | F23: Металлопрокат
A24: 9
A25: 10
A26: 11
A27: 12
A28: 13
A29: 14
A30: 15
A31: 16
A32: 17
A33: 18
A34: 19
A35: 20
B36: Коммерческий отдел (ЛОГИСТИКА / Хранение / ПРР)
A37: 1 | B37: Голка | C37: НЕО ТРАНС ООО | D37: Счет №3730 от 13.02 | E37: 80000 | F37: Транспорт | G37: РТПЗ Волжский | H37: Бюджет | K37: оплачен
A38: 2
A39: 3 | B39: Голка | C39: Картавцев ИП | D39: Счет №1 от 13.02 | E39: 60000 | F39: Транспорт | G39: РТПЗ Волжский | H39: Бюджет | K39: оплачен
A40: 4 | B40: Голка | C40: Донцов ИП | D40: Счет №4 от 24.02 | E40: 8500 | F40: Транспорт | G40: РТПЗ Волжский | H40: Бюджет | K40: оплачен
A41: 5 | B41: Голка | C41: ДЕЛКО ООО | D41: Счет №14701 от 13.02 | E41: 55000 | F41: Транспорт | G41: РТПЗ Волжский | H41: Бюджет | K41: оплачен
A42: 6 | B42: Голка | C42: МЭТ ООО | D42: Счет №739/2026 от 12.02 | E42: 70000 | F42: Транспорт | G42: РТПЗ Волжский | H42: Бюджет | K42: оплачен
A43: 7 | B43: Голка | C43: АРКС ЛОГИСТИК ООО | D43: Счет №96 от 12.02 | E43: 45000 | F43: Транспорт | G43: РТПЗ Волжский | H43: Бюджет | K43: оплачен
...

Sheet 17
C2: ='16'!C2+1 -> 46098
A4: ООО ТД РТПЗ | E4: =SUM(E5:E12) -> 2760254.2 | F4: РЕЕСТР ЗАКРЫТ !!!
A5: Волжский счёт СБ 7503 | E5: 2481477.2
A6: Головной счёт СБ 13291 | E6: 4429.92
A7: ИП Коваленко СБ 17500
A8: счёт ЦМР Банк | E8: 15821.6
A9: счёт РОСБАНК 1115 | E9: 49366.84
A10: счёт Райффайзенбанк 38867 | E10: 134865.61
A11: счёт Промсвязьбанк 5439 | E11: 31489.09
A12: счёт Альфа-Банк 10329 | E12: 42803.93
A14: № п/п | B14: Инициатор платежа | C14: Контрагент - Получатель | D14: Договор/Счет | E14: Сумма к оплате | F14: Назначение платежа | G14: Подразделение - плательщик | H14: Бюджет/Статья | I14: Наличие Договора | J14: Примечание | K14: Отметка об оплате | L14: Спец. Распоряжение
B15: Коммерческий отдел (ПОСТАВЩИКИ / ПОКУПАТЕЛИ)
A16: 2 | B16: Федоров А.А. | C16: Северсталь ПАО | D16: Договр № 643/1000-24100303 от 12.04.2024 | E16: .25 933 135,75 | F16: Металлопрокат
A17: 3 | B17: Федоров А.А. | C17: НЛМК ПАО | D17: Договор №204709-23 от 15.03.2023 | E17: 2000000 | F17: Металлопрокат | K17: оплачен
A18: 6
A19: 7 | B19: Ченский М.В. | C19: СтройПартнёр ООО | D19: Договор №СП23-00689-КР от 12.07.2023 | E19: 671152.5 | F19: Металлопрокат | K19: оплачен
A20: 8 | B20: Ченский М.В. | C20: Мечел-Сервис ООО | D20: Договор №370019010049 от 01.04.2019 | E20: 263219.23 | F20: Металлопрокат | K20: оплачен
A21: 9
A22: 10
A23: 11
A24: 12
A25: 13
A26: 14
A27: 15
A28: 16
A29: 17
A30: 18
A31: 19
A32: 20
B33: Коммерческий отдел (ЛОГИСТИКА / Хранение / ПРР)
A34: 1
A35: 2
A36: 3
A37: 4
A38: 5
A39: 6
A40: 7
A41: 8
A42: 9
A43: 10
...

Sheet 18
C2: ='17'!C2+1 -> 46099
A4: ООО ТД РТПЗ | E4: =SUM(E5:E12) -> 11353586 | F4: РЕЕСТР ЗАКРЫТ !!!
A5: Волжский счёт СБ 7503 | E5: 9061924.1
A6: Головной счёт СБ 13291 | E6: 27855.3
A7: ИП Коваленко СБ 17500
A8: счёт ЦМР Банк | E8: 15821.6
A9: счёт РОСБАНК 1115 | E9: 47366.84
A10: счёт Райффайзенбанк 38867 | E10: 126325.61
A11: счёт Промсвязьбанк 5439 | E11: 2031489.1
A12: счёт Альфа-Банк 10329 | E12: 42803.93
A14: № п/п | B14: Инициатор платежа | C14: Контрагент - Получатель | D14: Договор/Счет | E14: Сумма к оплате | F14: Назначение платежа | G14: Подразделение - плательщик | H14: Бюджет/Статья | I14: Наличие Договора | J14: Примечание | K14: Отметка об оплате | L14: Спец. Распоряжение
B15: Коммерческий отдел (ПОСТАВЩИКИ / ПОКУПАТЕЛИ)
A16: 1 | B16: Ченский М.В. | C16: СтройПартнёр ООО | D16: Договор №СП23-00689-КР от 12.07.2023 | E16: 725760 | F16: Металлопрокат | K16: оплачен
A17: 2
A18: 3 | B18: Федоров А.А. | C18: Северсталь ПАО | D18: Договр № 643/1000-24100303 от 12.04.2024 | E18: .25 933 135,75 | F18: Металлопрокат
A19: 4
A20: 5
A21: 6
A22: 7
A23: 8
A24: 9
A25: 10
A26: 11
A27: 12
A28: 13
A29: 14
A30: 15
... A35: 20
B36: Коммерческий отдел (ЛОГИСТИКА / Хранение / ПРР)
A37: 1 | B37: Голка | C37: Третьяков ИП | D37: Счет №260012601,26012801,26021101 от 11.02 | E37: =65000+78000+85000 -> 228000 | F37: Транспорт | G37: РТПЗ Волжский | H37: Бюджет | I37: Да | K37: оплачен
A38: 2 | B38: Голка | C38: Бабенко А.В. ИП | D38: Счет №54 от 27.02 | E38: 55000 | F38: Транспорт | G38: РТПЗ Волжский | H38: Бюджет | I38: Да | K38: оплачен
A39: 3 | B39: Голка | C39: Качурин М.О. ИП | D39: Счет №324 от 17.02 | E39: 52000 | F39: Транспорт | G39: РТПЗ Волжский | H39: Бюджет | I39: Да | K39: оплачен
A40: 4
A41: 5 | B41: Голка | C41: Ушаков А.С. ИП | D41: Счет №82 от 18.02 | E41: 80000 | F41: Транспорт | G41: РТПЗ Волжский | H41: Бюджет | I41: Да | J41: Копия | K41: оплачен
A42: 6 | B42: Голка | C42: ДЕЛКО ООО | D42: Счет №16152 от 18.02 | E42: 55000 | F42: Транспорт | G42: РТПЗ Волжский | H42: Бюджет | I42: Да | K42: оплачен
A43: 7 | B43: Голка | C43: Исаев М.Е. ИП | D43: Счет №13 от 11.03 | E43: 33000 | F43: Транспорт | G43: РТПЗ Волжский | H43: Бюджет | I43: Да | K43: оплачен
A44: 8 | B44: Голка | C44: СКС-Групп ООО | D44: Счет №36 от 13.02 | E44: 37000 | F44: Транспорт | G44: РТПЗ Волжский | H44: Бюджет | I44: Да | K44: оплачен
A45: 9 | B45: Голка | C45: РАУТ ООО | D45: Счет №12,14,17 от 16.02 | E45: =80000+62000+62000 -> 204000 | F45: Транспорт | G45: РТПЗ Волжский | H45: Бюджет | I45: Да | K45: оплачен
A46: 10 | B46: Голка | C46: Стальстройпоставка ООО | D46: Счет №106,105,108,125,140,131,352 от 18.02 | E46: =40000+70000+40000+85000+40000+48000+60000 -> 383000 | F46: Транспорт | G46: РТПЗ Волжский | H46: Бюджет | I46: Да | J46: Скан | K46: оплачен
A47: 11 | B47: Голка | C47: Ахметов А.С. ИП | D47: По Акту сверки от 17.02 | E47: 35000 | F47: Транспорт | G47: РТПЗ Волжский | H47: Бюджет | I47: Да | K47: оплачен
...

Sheet 19
C2: ='18'!C2+1 -> 46100
A4: ООО ТД РТПЗ | E4: =SUM(E5:E12) -> 9498017.4 | F4: РЕЕСТР ЗАКРЫТ !!!
A5: Волжский счёт СБ 7503 | E5: 6713089
A6: Головной счёт СБ 13291 | E6: 27855.3
A7: ИП Коваленко СБ 17500
A8: счёт ЦМР Банк | E8: 15821.6
A9: счёт РОСБАНК 1115 | E9: 47366.84
A10: счёт Райффайзенбанк 38867 | E10: 626325.61
A11: счёт Промсвязьбанк 5439 | E11: 2024755.1
A12: счёт Альфа-Банк 10329 | E12: 42803.93
A14: № п/п | B14: Инициатор платежа | C14: Контрагент - Получатель | D14: Договор/Счет | E14: Сумма к оплате | F14: Назначение платежа | G14: Подразделение - плательщик | H14: Бюджет/Статья | I14: Наличие Договора | J14: Примечание | K14: Отметка об оплате | L14: Спец. Распоряжение
B15: Коммерческий отдел (ПОСТАВЩИКИ / ПОКУПАТЕЛИ)
A16: 1 | B16: Федоров А.А. | C16: НЛМК ПАО | D16: Договор №204709-23 от 15.03.2023 | E16: 8000000 | F16: Металлопрокат | K16: оплачен
A17: 2
A18: 3
A19: 4
A20: 5
A21: 6
A22: 7
A23: 8
A24: 9
A25: 10
A26: 11
A27: 12
A28: 13
... A35: 20
B36: Коммерческий отдел (ЛОГИСТИКА / Хранение / ПРР)
A37: 1
A38: 2
A39: 3
A40: 4
A41: 5
A42: 6
A43: 7
A44: 8
A45: 9
A46: 10
A47: 11
A48: 12
... A56: 20
...

Sheet 20
C2: ='19'!C2+1 -> 46101
A4: ООО ТД РТПЗ | E4: =SUM(E5:E12) -> 2833471.3 | F4: РЕЕСТР ЗАКРЫТ !!!
A5: Волжский счёт СБ 7503 | E5: 614473.9
A6: Головной счёт СБ 13291 | E6: 27855.3
A7: ИП Коваленко СБ 17500
A8: счёт ЦМР Банк | E8: 15821.6
A9: счёт РОСБАНК 1115 | E9: 47366.84
A10: счёт Райффайзенбанк 38867 | E10: 2060394.6
A11: счёт Промсвязьбанк 5439 | E11: 24755.09
A12: счёт Альфа-Банк 10329 | E12: 42803.93
A14: № п/п | B14: Инициатор платежа | C14: Контрагент - Получатель | D14: Договор/Счет | E14: Сумма к оплате | F14: Назначение платежа | G14: Подразделение - плательщик | H14: Бюджет/Статья | I14: Наличие Договора | J14: Примечание | K14: Отметка об оплате | L14: Спец. Распоряжение
B15: Коммерческий отдел (ПОСТАВЩИКИ / ПОКУПАТЕЛИ)
A16: 1 | B16: Ченский М.В. | C16: Сталепромышленная компания АО | D16: Договор поставки № 30/2019 от 02.04.2019 | E16: 486090 | F16: Металлопрокат | K16: оплачен
A17: 2 | C17: кармет | E17: 3000000 | J17: с райфа | K17: оплачен
A18: 3 | B18: Федоров А.А. | C18: Северсталь ПАО | D18: Договр № 643/1000-24100303 от 12.04.2024 | E18: .25 933 135,75 | F18: Металлопрокат
A19: 4 | B19: Федоров А.А. | C19: НЛМК ПАО | D19: Договор №204709-23 от 15.03.2023 | E19: 5000000 | F19: Металлопрокат | K19: оплачен
A20: 5
A21: 6
A22: 7
A23: 8
A24: 9
A25: 10
A26: 11
A27: 12
A28: 13
A29: 14
A30: 15
A31: 16
... A35: 20
B36: Коммерческий отдел (ЛОГИСТИКА / Хранение / ПРР)
A37: 1
A38: 2
A39: 3
A40: 4
A41: 5
A42: 6
A43: 7
A44: 8
A45: 9
A46: 10
...

Sheet 21
C2: ='20'!C2+1 -> 46102
A4: ООО ТД РТПЗ | E4: =SUM(E5:E12) -> 0
A5: Волжский счёт СБ 7503
A6: Головной счёт СБ 13291
A7: ИП Коваленко СБ 17500
A8: счёт ЦМР Банк
A9: счёт РОСБАНК 1115
A10: счёт Райффайзенбанк 38867
A11: счёт Промсвязьбанк 5439
A12: счёт Альфа-Банк 10329
A14: № п/п | B14: Инициатор платежа | C14: Контрагент - Получатель | D14: Договор/Счет | E14: Сумма к оплате | F14: Назначение платежа | G14: Подразделение - плательщик | H14: Бюджет/Статья | I14: Наличие Договора | J14: Примечание | K14: Отметка об оплате | L14: Спец. Распоряжение
B15: Коммерческий отдел (ПОСТАВЩИКИ / ПОКУПАТЕЛИ)
A16: 1
A17: 2
A18: 3
A19: 4
A20: 5
A21: 6
A22: 7
A23: 8
A24: 9
A25: 10
A26: 11
A27: 12
... A35: 20
B36: Коммерческий отдел (ЛОГИСТИКА / Хранение / ПРР)
A37: 1
A38: 2
A39: 3
A40: 4
A41: 5
A42: 6
A43: 7
A44: 8
A45: 9
A46: 10
A47: 11
A48: 12
... A56: 20
B57: ПРОИЗВОДСТВЕННЫЙ комплекс / ТЕХ служба
...

Sheet 22
C2: ='21'!C2+1 -> 46103
A4: ООО ТД РТПЗ | E4: =SUM(E5:E12) -> 0
A5: Волжский счёт СБ 7503
A6: Головной счёт СБ 13291
A7: ИП Коваленко СБ 17500
A8: счёт ЦМР Банк
A9: счёт РОСБАНК 1115
A10: счёт Райффайзенбанк 38867
A11: счёт Промсвязьбанк 5439
A12: счёт Альфа-Банк 10329
A14: № п/п | B14: Инициатор платежа | C14: Контрагент - Получатель | D14: Договор/Счет | E14: Сумма к оплате | F14: Назначение платежа | G14: Подразделение - плательщик | H14: Бюджет/Статья | I14: Наличие Договора | J14: Примечание | K14: Отметка об оплате | L14: Спец. Распоряжение
B15: Коммерческий отдел (ПОСТАВЩИКИ / ПОКУПАТЕЛИ)
A16: 1
A17: 2
A18: 3
A19: 4
A20: 5
A21: 6
A22: 7
A23: 8
A24: 9
A25: 10
A26: 11
A27: 12
... A35: 20
B36: Коммерческий отдел (ЛОГИСТИКА / Хранение / ПРР)
A37: 1
A38: 2
A39: 3
A40: 4
A41: 5
A42: 6
A43: 7
A44: 8
A45: 9
A46: 10
A47: 11
A48: 12
... A56: 20
B57: ПРОИЗВОДСТВЕННЫЙ комплекс / ТЕХ служба
...

Sheet 23
C2: ='22'!C2+1 -> 46104
A4: ООО ТД РТПЗ | E4: =SUM(E5:E12) -> 3963253.9 | F4: РЕЕСТР ЗАКРЫТ !!!
A5: Волжский счёт СБ 7503 | E5: 277491.7 | F5: =E35+E36+E37+E38+E39+E40+E41+E42+E43+E44+E45+E46+'25'!E37+'25'!E38+'25'!E39+'25'!E76+'25'!E41+'25'!E42+'25'!E43+'25'!E44+'25'!E45+'25'!E46+E99+E100 -> 5038141.5
A6: Головной счёт СБ 13291 | E6: 27855.3
A7: ИП Коваленко СБ 17500
A8: счёт ЦМР Банк | E8: 15821.6
A9: счёт РОСБАНК 1115 | E9: 47366.84
A10: счёт Райффайзенбанк 38867 | E10: 2537844.4
A11: счёт Промсвязьбанк 5439 | E11: 1014070.2
A12: счёт Альфа-Банк 10329 | E12: 42803.93
A14: № п/п | B14: Инициатор платежа | C14: Контрагент - Получатель | D14: Договор/Счет | E14: Сумма к оплате | F14: Назначение платежа | G14: Подразделение - плательщик | H14: Бюджет/Статья | I14: Наличие Договора | J14: Примечание | K14: Отметка об оплате | L14: Спец. Распоряжение
B15: Коммерческий отдел (ПОСТАВЩИКИ / ПОКУПАТЕЛИ)
A16: 1
A17: 2 | C17: кармет | E17: 2500000 | K17: оплачен
A18: 3
A19: 6 | B19: Федоров А.А. | C19: Северсталь ПАО | D19: Договр № 643/1000-24100303 от 12.04.2024 | E19: .25 933 135,75 | F19: Металлопрокат | I19: Да
A20: 7 | B20: Федоров А.А. | C20: НЛМК ПАО | D20: Договор №204709-23 от 15.03.2023 | F20: Металлопрокат | I20: Да
A21: 8
A22: 9
A23: 10
A24: 11
A25: 12
A26: 13
A27: 14
A28: 15
A29: 16
A30: 17
A31: 18
A32: 19
A33: 20
B34: Коммерческий отдел (ЛОГИСТИКА / Хранение / ПРР)
A35: 1 | B35: Высокова | C35: ИП Хачатрян | D35: Счет № 17 от 05.03.2026 | E35: 900 | F35: Транспорт | H35: Бюджет | I35: Да | K35: оплачен
A36: 2 | B36: Голка | C36: Воробьев А.Н. ИП | D36: Счет №31 от 17.02 | E36: 100000 | F36: Транспорт | G36: РТПЗ Волжский | H36: Бюджет | I36: Да | K36: оплачен
A37: 3 | B37: Голка | C37: Делко ООО | D37: Счет №17677 от 19.02 | E37: 120000 | F37: Транспорт | G37: РТПЗ Волжский | H37: Бюджет | I37: Да | K37: оплачен
A38: 4 | B38: Голка | C38: Третьяков В.И. | D38: Счет №25120501 от 05.12 | E38: 85000 | F38: Транспорт | G38: РТПЗ Волжский | H38: Бюджет | I38: Да | K38: оплачен
A39: 5 | B39: Голка | C39: АК№2 ООО | D39: Счет №1998,1995 от 18.02 | E39: =85000+85000 -> 170000 | F39: Транспорт | G39: РТПЗ Волжский | H39: Бюджет | I39: Да | K39: оплачен
A40: 6 | B40: Голка | C40: Качурин М.О. ИП | D40: Счет №350 от 20.02 | E40: 50000 | F40: Транспорт | G40: РТПЗ Волжский | H40: Бюджет | K40: оплачен
A41: 7 | B41: Голка | C41: ТК Никотранс ООО | D41: Счет №3526 от 20.02 | E41: 75000 | F41: Транспорт | G41: РТПЗ Волжский | H41: Бюджет | I41: Да | J41: КОПИЯ | K41: оплачен
A42: 8 | B42: Голка | C42: Долотказин Р.Р ИП | D42: Счет №13 от 20.02 | E42: 55000 | F42: Транспорт | G42: РТПЗ Волжский | H42: Бюджет | I42: Да | K42: оплачен
A43: 9 | B43: Голка | C43: Ес-Логистик ООО | D43: Счет №489 от 18.02 | E43: 72000 | F43: Транспорт | G43: РТПЗ Волжский | H43: Бюджет | I43: Да | J43: КОПИЯ | K43: оплачен
...

Sheet 24
C2: ='23'!C2+1 -> 46105
A4: ООО ТД РТПЗ | E4: =SUM(E5:E12) -> 10200091 | F4: РЕЕСТР ЗАКРЫТ !!!
A5: Волжский счёт СБ 7503 | E5: 5053775.6
A6: Головной счёт СБ 13291 | E6: 26252.91
A7: ИП Коваленко СБ 17500
A8: счёт ЦМР Банк | E8: 15821.6
A9: счёт РОСБАНК 1115 | E9: 47366.84
A10: счёт Райффайзенбанк 38867 | E10: 30501.41
A11: счёт Промсвязьбанк 5439 | E11: 4014070.1
A12: счёт Альфа-Банк 10329 | E12: 1042803.9
A14: № п/п | B14: Инициатор платежа | C14: Контрагент - Получатель | D14: Договор/Счет | E14: Сумма к оплате | F14: Назначение платежа | G14: Подразделение - плательщик | H14: Бюджет/Статья | I14: Наличие Договора | J14: Примечание | K14: Отметка об оплате | L14: Спец. Распоряжение
B15: Коммерческий отдел (ПОСТАВЩИКИ / ПОКУПАТЕЛИ)
A16: 1
A17: 2
A18: 3 | B18: Федоров А.А. | C18: Северсталь ПАО | D18: Договр № 643/1000-24100303 от 12.04.2024 | E18: .25 933 135,75 | F18: Металлопрокат
A19: 4 | B19: Федоров А.А. | C19: НЛМК ПАО | D19: Договор №204709-23 от 15.03.2023 | E19: 5000000 | F19: Металлопрокат | K19: оплачен
A20: 5
A21: 6
A22: 7
A23: 8
A24: 9
A25: 10
A26: 11
A27: 12
A28: 13
A29: 14
A30: 15
A31: 16
... A35: 20
B36: Коммерческий отдел (ЛОГИСТИКА / Хранение / ПРР)
A37: 1
A38: 2
A39: 3
A40: 4
A41: 5
A42: 6
A43: 7
A44: 8
A45: 9
A46: 10
...

Sheet 25
C2: ='24'!C2+1 -> 46106
A4: ООО ТД РТПЗ | E4: =SUM(E5:E12) -> 629398.13 | F4: РЕЕСТР ЗАКРЫТ !!!
A5: Волжский счёт СБ 7503 | E5: 483082.7
A6: Головной счёт СБ 13291 | E6: 26252.91
A7: ИП Коваленко СБ 17500
A8: счёт ЦМР Банк | E8: 15821.6
A9: счёт РОСБАНК 1115 | E9: 47366.84
A10: счёт Райффайзенбанк 38867 | E10: 30501.41
A11: счёт Промсвязьбанк 5439 | E11: 14070.15
A12: счёт Альфа-Банк 10329 | E12: 42803.93
A14: № п/п | B14: Инициатор платежа | C14: Контрагент - Получатель | D14: Договор/Счет | E14: Сумма к оплате | F14: Назначение платежа | G14: Подразделение - плательщик | H14: Бюджет/Статья | I14: Наличие Договора | J14: Примечание | K14: Отметка об оплате | L14: Спец. Распоряжение
B15: Коммерческий отдел (ПОСТАВЩИКИ / ПОКУПАТЕЛИ)
A16: 1
A17: 2 | B17: Федоров А.А. | C17: Северсталь ПАО | D17: Договр № 643/1000-24100303 от 12.04.2024 | E17: .25 933 135,75 | F17: Металлопрокат | I17: Да
A18: 3 | B18: Федоров А.А. | C18: НЛМК ПАО | D18: Договор №204709-23 от 15.03.2023 | F18: Металлопрокат | I18: Да
A19: 4
A20: 5
A21: 6
A22: 7
A23: 8
A24: 9
A25: 10
A26: 11
A27: 12
A28: 13
A29: 14
A30: 15
... A35: 20
B36: Коммерческий отдел (ЛОГИСТИКА / Хранение / ПРР)
A37: 1 | B37: Голка | C37: Кузнеченков И.А. ИП | D37: Счет №21 от 05.03 | E37: 45000 | F37: Транспорт | G37: РТПЗ Волжский | H37: Бюджет | K37: оплачен
A38: 2 | B38: Голка | C38: Настина Т.В. ИП | D38: Счет №56,50,58,59 от 14.03 | E38: =65000+62000+75000+74000 -> 276000 | F38: Транспорт | G38: РТПЗ Волжский | H38: Бюджет | K38: оплачен
A39: 3 | B39: Голка | C39: Третьяков ИП | D39: Счет №402,401 от 24.02 | E39: =65000+85000 -> 150000 | F39: Транспорт | G39: РТПЗ Волжский | H39: Бюджет | K39: оплачен
A40: 4 | B40: Голка | C40: Кушнарев Ю.Н. ИП | D40: Счет №9 от 16.02 | E40: 85000 | F40: Транспорт | G40: РТПЗ Волжский | H40: Бюджет | K40: оплачен
A41: 5 | B41: Голка | C41: Ушаков А.С. ИП | D41: Счет №89 от 24.02 | E41: 80000 | F41: Транспорт | G41: РТПЗ Волжский | H41: Бюджет | K41: оплачен
A42: 6 | B42: Голка | C42: Исаев ИП | D42: Счет №15 от 16.03 | E42: 34000 | F42: Транспорт | G42: РТПЗ Волжский | H42: Бюджет | K42: оплачен
A43: 7
A44: 8
A45: 9
A46: 10
A47: 11
...

Sheet 26
C2: ='25'!C2+1 -> 46107
A4: ООО ТД РТПЗ | E4: =SUM(E5:E12) -> 6253760.7 | F4: РЕЕСТР ЗАКРЫТ !!!
A5: Волжский счёт СБ 7503 | E5: 6077481.9
A6: Головной счёт СБ 13291 | E6: 26252.91
A7: ИП Коваленко СБ 17500
A8: счёт ЦМР Банк | E8: 15821.6
A9: счёт РОСБАНК 1115
A10: счёт Райффайзенбанк 38867 | E10: 24401.41
A11: счёт Промсвязьбанк 5439 | E11: 66998.95
A12: счёт Альфа-Банк 10329 | E12: 42803.93
A14: № п/п | B14: Инициатор платежа | C14: Контрагент - Получатель | D14: Договор/Счет | E14: Сумма к оплате | F14: Назначение платежа | G14: Подразделение - плательщик | H14: Бюджет/Статья | I14: Наличие Договора | J14: Примечание | K14: Отметка об оплате | L14: Спец. Распоряжение
B15: Коммерческий отдел (ПОСТАВЩИКИ / ПОКУПАТЕЛИ)
A16: 1
A17: 2 | B17: Федоров А.А. | C17: Северсталь ПАО | D17: Договр № 643/1000-24100303 от 12.04.2024 | E17: .25 933 135,75 | F17: Металлопрокат | I17: Да
A18: 3 | B18: Федоров А.А. | C18: НЛМК ПАО | D18: Договор №204709-23 от 15.03.2023 | F18: Металлопрокат | I18: Да
A19: 4
A20: 5
A21: 6
A22: 7
A23: 8
A24: 9
A25: 10
A26: 11
A27: 12
A28: 13
A29: 14
A30: 15
... A35: 20
B36: Коммерческий отдел (ЛОГИСТИКА / Хранение / ПРР)
A37: 1
A38: 2
A39: 3
A40: 4
A41: 5
A42: 6
A43: 7
A44: 8
A45: 9
A46: 10
A47: 11
...

Sheet 27
C2: ='26'!C2+1 -> 46108
A4: ООО ТД РТПЗ | E4: =SUM(E5:E12) -> 3479181.5 | F4: РЕЕСТР ЗАКРЫТ !!!
A5: Волжский счёт СБ 7503 | E5: 3205641.6
A6: Головной счёт СБ 13291 | E6: 10252.91
A7: ИП Коваленко СБ 17500
A8: счёт ЦМР Банк | E8: 15821.6
A9: счёт РОСБАНК 1115 | E9: 43366.84
A10: счёт Райффайзенбанк 38867 | E10: 94295.62
A11: счёт Промсвязьбанк 5439 | E11: 66998.95
A12: счёт Альфа-Банк 10329 | E12: 42803.93
A14: № п/п | B14: Инициатор платежа | C14: Контрагент - Получатель | D14: Договор/Счет | E14: Сумма к оплате | F14: Назначение платежа | G14: Подразделение - плательщик | H14: Бюджет/Статья | I14: Наличие Договора | J14: Примечание | K14: Отметка об оплате | L14: Спец. Распоряжение
B15: Коммерческий отдел (ПОСТАВЩИКИ / ПОКУПАТЕЛИ)
A16: 1 | B16: Федоров А.А. | C16: Северсталь ПАО | D16: Договр № 643/1000-24100303 от 12.04.2024 | E16: .25 933 135,75 | F16: Металлопрокат
A17: 2 | B17: Федоров А.А. | C17: НЛМК ПАО | D17: Договор №204709-23 от 15.03.2023 | E17: 5000000 | F17: Металлопрокат | K17: оплачен
A18: 3
A19: 4
A20: 5
A21: 6
A22: 7
A23: 8
A24: 9
A25: 10
A26: 11
A27: 12
A28: 13
A29: 14
... A35: 20
B36: Коммерческий отдел (ЛОГИСТИКА / Хранение / ПРР)
A37: 1
A38: 2
A39: 3
A40: 4
A41: 5
A42: 6
A43: 7
A44: 8
A45: 9
A46: 10
A47: 11
A48: 12
...

Sheet 28
C2: ='27'!C2+1 -> 46109
A4: ООО ТД РТПЗ | E4: =SUM(E5:E12) -> 0
A5: Волжский счёт СБ 7503
A6: Головной счёт СБ 13291
A7: ИП Коваленко СБ 17500
A8: счёт ЦМР Банк
A9: счёт РОСБАНК 1115
A10: счёт Райффайзенбанк 38867
A11: счёт Промсвязьбанк 5439
A12: счёт Альфа-Банк 10329
A14: № п/п | B14: Инициатор платежа | C14: Контрагент - Получатель | D14: Договор/Счет | E14: Сумма к оплате | F14: Назначение платежа | G14: Подразделение - плательщик | H14: Бюджет/Статья | I14: Наличие Договора | J14: Примечание | K14: Отметка об оплате | L14: Спец. Распоряжение
B15: Коммерческий отдел (ПОСТАВЩИКИ / ПОКУПАТЕЛИ)
A16: 1
A17: 2
A18: 3
A19: 4
A20: 5
A21: 6
A22: 7
A23: 8
A24: 9
A25: 10
A26: 11
A27: 12
... A35: 20
B36: Коммерческий отдел (ЛОГИСТИКА / Хранение / ПРР)
A37: 1
A38: 2
A39: 3
A40: 4
A41: 5
A42: 6
A43: 7
A44: 8
A45: 9
A46: 10
A47: 11
A48: 12
... A56: 20
B57: ПРОИЗВОДСТВЕННЫЙ комплекс / ТЕХ служба
...

Sheet 29
C2: ='28'!C2+1 -> 46110
A4: ООО ТД РТПЗ | E4: =SUM(E5:E12) -> 0
A5: Волжский счёт СБ 7503
A6: Головной счёт СБ 13291
A7: ИП Коваленко СБ 17500
A8: счёт ЦМР Банк
A9: счёт РОСБАНК 1115
A10: счёт Райффайзенбанк 38867
A11: счёт Промсвязьбанк 5439
A12: счёт Альфа-Банк 10329
A14: № п/п | B14: Инициатор платежа | C14: Контрагент - Получатель | D14: Договор/Счет | E14: Сумма к оплате | F14: Назначение платежа | G14: Подразделение - плательщик | H14: Бюджет/Статья | I14: Наличие Договора | J14: Примечание | K14: Отметка об оплате | L14: Спец. Распоряжение
B15: Коммерческий отдел (ПОСТАВЩИКИ / ПОКУПАТЕЛИ)
A16: 1
A17: 2
A18: 3
A19: 4
A20: 5
A21: 6
A22: 7
A23: 8
A24: 9
A25: 10
A26: 11
A27: 12
... A35: 20
B36: Коммерческий отдел (ЛОГИСТИКА / Хранение / ПРР)
A37: 1
A38: 2
A39: 3
A40: 4
A41: 5
A42: 6
A43: 7
A44: 8
A45: 9
A46: 10
A47: 11
A48: 12
... A56: 20
B57: ПРОИЗВОДСТВЕННЫЙ комплекс / ТЕХ служба
...

Sheet 30
C2: ='29'!C2+1 -> 46111
A4: ООО ТД РТПЗ | E4: =SUM(E5:E12) -> 5923231.6 | F4: РЕЕСТР ЗАКРЫТ !!!
A5: Волжский счёт СБ 7503 | E5: 4649691.7
A6: Головной счёт СБ 13291 | E6: 10252.91
A7: ИП Коваленко СБ 17500
A8: счёт ЦМР Банк | E8: 15821.6
A9: счёт РОСБАНК 1115 | E9: 43366.84
A10: счёт Райффайзенбанк 38867 | E10: 94295.62
A11: счёт Промсвязьбанк 5439 | E11: 1066998.9
A12: счёт Альфа-Банк 10329 | E12: 42803.93
A14: № п/п | B14: Инициатор платежа | C14: Контрагент - Получатель | D14: Договор/Счет | E14: Сумма к оплате | F14: Назначение платежа | G14: Подразделение - плательщик | H14: Бюджет/Статья | I14: Наличие Договора | J14: Примечание | K14: Отметка об оплате | L14: Спец. Распоряжение
B15: Коммерческий отдел (ПОСТАВЩИКИ / ПОКУПАТЕЛИ)
A16: 1 | B16: Федоров А.А. | C16: Северсталь ПАО | D16: Договр № 643/1000-24100303 от 12.04.2024 | E16: .25 933 135,75 | F16: Металлопрокат | I16: Да
A17: 2 | B17: Федоров А.А. | C17: НЛМК ПАО | D17: Договор №204709-23 от 15.03.2023 | F17: Металлопрокат | I17: Да
A18: 3 | B18: Федоров А.А. | C18: Сталепромышленная компания АО | D18: Договор поставки № 30/2019 от 02.04.2019 | E18: .977032,5 | F18: Металлопрокат | I18: Да
A19: 4
A20: 5
A21: 6
A22: 7
A23: 8
A24: 9
A25: 10
A26: 11
A27: 12
A28: 13
A29: 14
A30: 15
... A35: 20
B36: Коммерческий отдел (ЛОГИСТИКА / Хранение / ПРР)
A37: 1
A38: 2
A39: 3
A40: 4
A41: 5
A42: 6
A43: 7
A44: 8
A45: 9
A46: 10
A47: 11
...

Sheet 31
C2: ='30'!C2+1 -> 46112
A4: ООО ТД РТПЗ | E4: =SUM(E5:E12) -> 1662698 | F4: РЕЕСТР ЗАКРЫТ !!!
A5: Волжский счёт СБ 7503 | E5: 1419968.1
A6: Головной счёт СБ 13291 | E6: 10252.91
A7: ИП Коваленко СБ 17500
A8: счёт ЦМР Банк | E8: 15821.6
A9: счёт РОСБАНК 1115 | E9: 43366.84
A10: счёт Райффайзенбанк 38867 | E10: 94272.62
A11: счёт Промсвязьбанк 5439 | E11: 66998.95
A12: счёт Альфа-Банк 10329 | E12: 12016.93
A14: № п/п | B14: Инициатор платежа | C14: Контрагент - Получатель | D14: Договор/Счет | E14: Сумма к оплате | F14: Назначение платежа | G14: Подразделение - плательщик | H14: Бюджет/Статья | I14: Наличие Договора | J14: Примечание | K14: Отметка об оплате | L14: Спец. Распоряжение
B15: Коммерческий отдел (ПОСТАВЩИКИ / ПОКУПАТЕЛИ)
A16: 1
A17: 2 | B17: Федоров А.А. | C17: Северсталь ПАО | D17: Договр № 643/1000-24100303 от 12.04.2024 | E17: .25 933 135,75 | F17: Металлопрокат | I17: Да
A18: 3 | B18: Федоров А.А. | C18: НЛМК ПАО | D18: Договор №204709-23 от 15.03.2023 | F18: Металлопрокат | I18: Да
A19: 4 | B19: Федоров А.А. | C19: Сталепромышленная компания АО | D19: Договор поставки № 30/2019 от 02.04.2019 | E19: .977032,5 | F19: Металлопрокат | I19: Да
A20: 5
A21: 6
A22: 7
A23: 8
A24: 9
A25: 10
A26: 11
A27: 12
A28: 13
A29: 14
A30: 15
A31: 16
... A35: 20
B36: Коммерческий отдел (ЛОГИСТИКА / Хранение / ПРР)
A37: 1
A38: 2
A39: 3
A40: 4
A41: 5
A42: 6
A43: 7
A44: 8
A45: 9
A46: 10
...

Sheet Тех.Лист
A1: Да
A2: Нет
